model
name = grass1
size = 17 13 18
scale = 0.05
origin = -y
material type = toon, lighting = smooth, deform = 1 1 
  colors = A:#690000 B:#740000
voxels
----------------- --A-------------- --A-------------- --A-------------- --A-------------- --A-------------- --A-------------- --B-------------- --B-------------- --A-------------- ----------------- ----------------- ----------------- 
-AA-------------- ----------------- ----------------- ----------------- ----------------- ----------------- ----------------- ----------------- ----------------- ----------------- ----------------- ----------------- ----------------- 
AAA-------------- AAA-------------- -AA-------------- -AA-------------- -AA-------------- -AA-------------- -BB-------------- --B-------------- --B-------------- ----------------- ----------------- ----------------- ----------------- 
AAA-------------- AAA-------------- -AA-------------- -A--------------- -A--------------- -A--------------- -A--------------- ----------------- ----------------- ----------------- ----------------- ----------------- ----------------- 
A--------------A- A--------------A- A--------------A- A--------------A- A--------------A- A--------------A- A--------------A- A--------------A- ---------------B- ----------------- ----------------- ----------------- ----------------- 
-----AA---------- -----AA---------- -----AA---------- -----AA---------- -----AA---------- -----AA---------- -----AA---------- -----A----------- -----A----------- -----A----------- ----------------- ----------------- ----------------- 
-----AA---------- -----AA---------- -----AA---------- -----AA---------- -----AA---------- ------A---------- ------A---------- ----------------- ----------------- ----------------- ----------------- ----------------- ----------------- 
-------------AA-- -------------AA-- -------------AA-- -------------AA-- -------------AA-- -------------AA-- -------------AA-- -------------AA-- --------------A-- --------------A-- --------------B-- --------------B-- ----------------- 
--------------A-- --------------A-- --------------A-- ----------------- ----------------- ----------------- ----------------- ----------------- ----------------- ----------------- ----------------- ----------------- ----------------- 
----------------- ----------------- ----------------- ----------------- ----------------- ----------------- ----------------- ----------------- ----------------- ----------------- ----------------- ----------------- ----------------- 
----------------- ----------------- ----------------- ----------------- ----------------- ----------------- ----------------- ----------------- ----------------- ----------------- ----------------- ----------------- ----------------- 
-----AAAA-------A -----AAAA-------A -----BBAA-------A -----BBAA-------A -----BBBB-------A -----BBBB-------- -----AAB--------- -----AAB--------- -------A--------- -------A--------- ----------------- ----------------- ----------------- 
-----AA--------AA -----AA---------- -----BB---------- -----BB---------- -----BB---------- -----BB---------- -----AA---------- -----AA---------- ----------------- ----------------- ----------------- ----------------- ----------------- 
-----AA--------AA -----AA---------- -----AA---------- -----AA---------- -----AA---------- -----AA---------- -----AA---------- -----AA---------- -----AA---------- ------A---------- ------A---------- ------A---------- ------A---------- 
-----AA--------A- -----AA--------A- -----AA---------- -----AA---------- -----AA---------- -----AA---------- ------A---------- ------A---------- ------A---------- ------A---------- ------A---------- ------A---------- ----------------- 
----------------- ----------------- ----------------- ----------------- ----------------- ----------------- ----------------- ----------------- ----------------- ----------------- ----------------- ----------------- ----------------- 
----------------- ----------------- ----------------- ----------------- ----------------- ----------------- ----------------- ----------------- ----------------- ----------------- ----------------- ----------------- ----------------- 
-AAAA------------ -AAAA------------ -AAAA------------ -AAA------------- -AAA------------- -AAA------------- -BB-------------- -BB-------------- -AA-------------- ----------------- ----------------- ----------------- ----------------- 
