model
name = main
revision = 3
size = 61 60 60
shape = sphere
scale = 0.017
origin = -y
shell = Outline 0.25
material lighting = smooth, fade = true, opacity = 0.35, deform = 3 1
  colors = B:#06F
material lighting = smooth, deform = 3 1, scatter = 0.5
  colors = F:#CCC
material deform = 3 1, scatter = 0.4
  colors = G:#FFF
material deform = 3 1, scatter = 0.3
  colors = E:#888
material lighting = smooth, fade = true, deform = 3 1, scatter = 0.2
  colors = C:#482 D:#6A4
material lighting = smooth, roughness = 0, deform = 3 1, scatter = 0.1
  colors = A:#04F
material type = basic, lighting = smooth, roughness = 0, refractionRatio = 1, side = back
  colors = Outline:#000
voxels
61(5-51B4-B)5-8F43B4-B5-14F37B4-B5-13F9B12F7B5F5B4-B5-4B4F13B13F6B7F4B4-B5-21B12F6B9F3B4-B5-40B9F2B4-B5-38BG2B7F2GF4-B5-39B2G2B5FG2F4-B5-37B3G5B3FG2F4-B5-21BF14B4G11B4-B5-19B4F8B4FB3G12B4-B5-19B6F7B4F4G11B4-B5-20B5F10B5G9BGB4-B5-G8B3F8B4F12B4G11B4-B5-2G8B12F15B3G11B4-B5-3G7B12F15B2G11BF4-B5-4G6B2FG9F12B4G12BG4-B5-13G4B4G2F10B3G2F13B4-B5-13G3B5G3F9B7F7B4G4-B5-F20G2F9B10F5B4G4-B5-F16G2B3G2F8B11F4B4G4-B5-F5B3GB3G5BFG5F9B6F9B2G4-B5-6B2G10B6F25B2G4-B5-19B3F28BG4-B5-11BG38BG4-B5-8BG42B4-B5-2F5BG26B5F11BG4-B5-2F5BG43B4-B5-3F48B4-B5-5F46B4-B5-7F36B4F4B4-B5-8F37B5FB4-B5-7F40B4F4-B5-5F43B3F4-B5-4F25B3F17B2F4-B5-3F25B8F15B4-B5-3F13B5F8B8F14B4-B5-3F14B5F29B4-B5-3F15B5F28B4-B5-4F14B6F20B6FB4-B5-4F15B5F17B10F4-B5-4F16B5F15B11F4-B5-4F17B4F14B12F4-B5-G4F16B5F12B13F4-B5-6F15B5F12B11F2B4-B5-2B5F14B3F14B6F7B4-B5-3B6F42B2(4-B5-51B)4-B5-21B2F27BF4-B5-43B8F4-B5-42B9F4-B5-41B10F4-B5-18B6F17B10F4-B5-16B9F16B10F4-B5-15B11F25B4-B5-15B14F22B4-B5-24B6F21B2(4-B5-51B)4-B5-4F47B4-B5-49B2E4-B5-47B4E4-B5-44BE2B2E2B4-B5-46BE2BEB4-B5-45B5EB4-B5-37BE2BEBE3B5E4-B5-36B3EB2E4B4EB4-B5-35B6E5B3EBE4-B5-36B6E4B4EB4-B5-34B8E7BEB4-B5-32B8E11B4-B5-E31BE2B5E9BEB4-B5-4E10BE6B3E9B9E7B2E4-B5-4EBE13B5E9B9E7B2E4-B5-5E12B6E9B10E8BE4-B5-6E2B16E8B11E7BE4-B5-23E9B7E2B2E5B3E4-B5-26E7B4E2B4E4B4E4-B5-25E22B4E4-B5-17EB6E23B4E4-B5-15E3(B2E)23B4E4-B5-2E3B5EB8E3B2E24B3E4-B5-E4B11E32B3E4-B5-5B11E5BE26B3E4-B5-5B7EB5E31B2E4-B5-3B7EB9E29B2E4-B5-5B5EBE2B6E31B4-B5-5B4E6BE35B4-B5-51B4-B5-16BE34B10(4-B5-51B)2(4-B5-E50B)4-B5-2E49B4-B5-E50B12(4-B5-51B)4-B5-14B16F21B2(4-B5-51B)4-B5-2F48BF4-B5-49B2E4-B5-23BE16BE4B6E2(4-B5-37BEB12E)4-B5-38BE2B3EB6E4-B5-34B5EB2EBEB6E4-B5-33B9E4B5E4-B5-E31B9E2B8E4-B5-E20BE9B11E2B7E4-B5-2E14B2E13B11E4B5E4-B5-4E7B2E3BE2B2E11B12E3BE2BE4-B5-5E3BE2B12E3BE5B11E4B2EBE4-B5-6EB20E4B13E4B3E4-B5-16EB7E7B15E3B2E4-B5-7E2B15E7B15E2B3E4-B5-25E6B16E3BE4-B5-26E3B16EBEB3E4-B5-27E3B21E4-B5-28E2B21E4-B5-28EB6E2BEB12E4-B5-28E3B2E5B13E4-B5-26E5B2E8BE4B5E4-B5-27E3B2E7B4E4B4E4-B5-2EB19E2B3E13B3E4B4E4-B5-23E19BE3BEB3E4-B5-B22E23B5E4-B5-2B19E26BE2BE4-B5-E2B18E26BE3B4-B5-E2B4E5B8EBE29B4-B5-2(E2B)E6B6EBE30B4-B5-4B2E8B6EBE29B4-B5-15B5E31B4-B5-15B2EB2E31B4-B5-15BE35B4-B5-50BE4-B5-14BE34B2E3(4-B5-51B)4-B5-E50B4-B5-51B2(4-B5-2E49B)2(4-B5-2EBE47B)4-B5-3EBE46B4-B5-2E2BE46B4-B5-4B2E45B4-B5-51B2(4-B5-3B2E46B)4-B5-6BE44B4-B5-2BE2B2E44B4-B5-2(2BE)45B4-B5-2B2E47B4-B5-51B4-B5-14B16F21B2(4-B5-51B)4-B5-F49BF4-B5-47BE2BE4-B5-22BE16BEBE2B7E4-B5-13BC8B3C10B16C4-B5-12B2C9B3C9B16C4-B5-12B2C7B5C5B20C4-B5-C10BC8B3CBC6B20C4-B5-3C17B2C8B13C2B6C4-B5-5C7B2(CB)2CB3C8B21C4-B5-7C4B12C7B21C4-B5-6C4B13C2BC5B20C4-B5-24C2BC4B20C4-B5-28C2B16CB4C4-B5-46C2B3C4-B5-48CB2C4-B5-51C4-B5-27CB23C5(4-B5-51C)4-B5-28CB6CB15C4-B5-34C2B15C4-B5-28CB5C2B15C4-B5-24C5B4C4B14C4-B5-23C15B13C4-B5-23C18B10C4-B5-22C21B8C4-B5-7CB15C25BC2B4-B5-6C6B10C3B3C23B4-B5-6C7B9C3B2C18BC4BC4-B5-6C8B8C27B2C4-B5-5C7BCB8C18BC7B3C4-B5-CBC9B4CBCB5C25B2C4-B5-11B6C2BC29B2C4-B5-3C8B3C2(B2C)19BC8B3C4-B5-C10B3CBC2B2C19B2C7B3C4-B5-C10B3C3B2C20B2C7BCBC4-B5-C11B2C37B4-B5-51B4-B5-2CBC47B4(4-B5-5C46B)4-B5-7C44B4-B5-CB4C45B4-B5-2B2CBC45B4-B5-2BCBC9BC36B4-B5-2B4C7BC37B4-B5-2B5C7BC36B4-B5-B6C44B4-B5-7C3BC40B4-B5-6C3BC41B4-B5-2B2E47B4-B5-51B4-B5-14B16F11B4F6B2(4-B5-51B)4-B5-F49BF4-B5-51B4-B5-42BE2(2B2E)4-B5-14BC7B3CBC10B14C4-B5-9B7C4B8C3BCB18C4-B5-10B5C5B8C2B21C4-B5-B2C7B5C5B7C3B21C4-B5-5C2BC2B16C4B21C4-B5-23CB3C2B22C17(4-B5-51C)4-B5-24C6B21C4-B5-25C6B8C2B10C4-B5-24CBC4BCB4CBC3B10C4-B5-26CB2C2B3C2B2CBC4B5CBC4-B5-6CB23C7B2C4B8C4-B5-7CBC4B17CBC8B11C4-B5-9C4B15CB2C9B11C4-B5-9C3B14C2B5C6B4CBC3B3C4-B5-7CB18C4B2(4C5B)3C4-B5-5C5B14CBC7B2C4B3C4B5C4-B5-5C3B15C16B2C7B3C4-B5-5C3B12C19B3C5B4C4-B5-3C6B11C19B3C5B4C4-B5-C11B2CB4C20B4C4B4C4-B5-11B3C3BC29B4C4-B5-3B2C7BC5BC29B3C4-B5-6C43B2C4-B5-6C7BCBC35B2(4-B5-6C45B)4-B5-7C44B4-B5-7C4B2C38B4-B5-B7C3B4C36B4-B5-B5C4B6C35B4-B5-B5C2B8C35B4-B5-B7CB8C34B4-B5-8CB7C35B4-B5-8CB5C37B4-B5-6C45B4-B5-4EBE45B4-B5-51B4-B5-15B14F10B7F5B2(4-B5-51B)4-B5-50BF2(4-B5-51B)4-B5-14BC6B2C2(BC)13B2C2B7C4-B5-11B4C5B8C7B16C4-B5-2B2D3BDB7D3B31D2(C4-B5-BC48D)21(C4-B5-2C48D)B4-B5-2C48DC4-B5-2C37DB10DC4-B5-2C36D2B10DC4-B5-2C36DB11DC4-B5-2C48DC4-B5-2C41D3B4DC4-B5-2C25D4B12D2B5DC4-B5-2C22DBD4BD2BD3B5D4B4DC4-B5-2C4D2B14D15B5D4B4DC4-B5-2C19D17B4D2BD2B3DC4-B5-2B4D2B14D16B4DB2D2B3DC4-B5-2B4DB15D22BDB4DC4-B5-2BDB2DB15D25B3DC4-B5-BC7DB11D27B2DC4-B5-BC5D4B5D2B5D28B4-B5-BC6D3B5D3B4D28B4-B5-2C5D3B6D3B4D28B4-B5-2C6D2B5D5B3D28B4-B5-BC5D2B7D2(35B4-B5-2B14D)BD33B4-B5-BC16D33B4-B5-BC15D34B4-B5-BC14D35B4-B5-7C5B2C37B4-B5-6C45B4-B5-4EBE45B4-B5-51B4-B5-20B9F10B7F5B2(4-B5-51B)4-B5-50BF2(4-B5-51B)4-B5-21B6C13BC7B3C4-B5-BC6BC2B4C5B9C6B8C2B6C4-B5-2B48DC4-B5-BC21(D46ADC4-B5-2C)D46ADB12(4-B5-2CD46ADC)3(4-B5-2BD46ADC)4-B5-BCD46ADC4-B5-BC2(D46ADB4-B5-2C)3(D46A2B4-B5-BC)D46A2B4-B5-2B2(D46A2B4-B5-2C)13D34BDB4-B5-8C3BC39B4-B5-6C45B4-B5-6E45B4-B5-51B4-B5-21B7F12B6F5B2(4-B5-51B)4-B5-50BF2(4-B5-51B)4-B5-12BC7B3C28B4-B5-B3C3B9C4B8C8B7C4B4C4-B5-BC48DC4-B5-BC21(D46ADC4-B5-2C)D46ADB12(4-B5-2CD46ADC)3(4-B5-2BD46ADC)4-B5-BC3(D46ADC4-B5-2C)2(D46ADB4-B5-BC)D46ADB4-B5-3B46ADB4-B5-2BD46ADB4-B5-2CD46A2B4-B5-2C13D34BDB4-B5-7C44B4-B5-6C45B4-B5-4E47B4-B5-51B4-B5-22B4F14B6F5B2(4-B5-51B)4-B5-12BF36B2F2(4-B5-51B)4-B5-19B3C29B4-B5-B25C11B4C7B3C4-B5-BC31DB16D34(C4-B5-2CD46AD)C4-B5-2BD3(46ADC4-B5-3B)2(46ADC4-B5-2BD)46ADC4-B5-BCD46ADC4(4-B5-2BD46ADB)4-B5-2CD46ADB4-B5-2C8D2B3D34BDB4-B5-9C42B4-B5-6C45B4-B5-B3E47B4-B5-51B4-B5-6B3F32B4F6B2(4-B5-51B)4-B5-11B4F33B3F2(4-B5-51B)4-B5-5B2C5BC2B6C30B4-B5-B22C12BC2B4C7B2C4-B5-BC24D6B11D2B5D15(C4-B5-2CD46AD)2(B4-B5-2CD46AD)9(C4-B5-2CD46AD)3(B4-B5-2CD46AD)5(C4-B5-2CD46AD)C4-B5-2BD4(46ADC4-B5-3B)2(46ADC4-B5-2BD)2(46ADB4-B5-3B)46ADB4-B5-2BD46ADB4-B5-BCD46ADB4-B5-2CD46ADB4-B5-BC9D38BDB4-B5-10C41B4-B5-7C44B4-B5-4E47B4-B5-2BE48B4-B5-5B5F32B2F7B2(4-B5-51B)4-B5-11B6F11BF19B3F2(4-B5-51B)4-B5-5B3CB4C2B3CBC31B4-B5-B21C27BCB4-B5-BC23D7B7D7B4DB4-B5-BC14(D46ADC4-B5-2C)2(D46ADB4-B5-BC)2(D46ADC4-B5-BC)7(D46ADC4-B5-2C)3(D46ADB4-B5-2C)5(D46ADC4-B5-2C)D5(46ADC4-B5-3B)2(46ADC4-B5-2BD)3(46ADB4-B5-2BD)2(46ADB4-B5-BCD)46ADB4-B5-BC8D39BDB4-B5-9C42B4-B5-6C45B4-B5-4E47B4-B5-51B4-B5-4B7F40B2(4-B5-51B)4-B5-11B8F7B4F16B5F2(4-B5-51B)4-B5-5B5C5BC3B2C30B4-B5-2B20C29B4-B5-BC23D6B5D11B3DC4-B5-BC13(D46ADC4-B5-2C)D46ADB4-B5-BCD46ADB2(4-B5-2CD46ADC4-B5-BCD46ADC)6(4-B5-2CD46ADC)4-B5-2CD46ADB9(4-B5-2CD46ADC)4-B5-2BD46ADC4-B5-3B4(46ADC4-B5-2BD)46ADC2(4-B5-3B46ADB)4-B5-2BD46ADB4-B5-BC2(D46ADB4-B5-2C)8D41B4-B5-9C42B4-B5-8C43B4-B5-B3E47B4-B5-51B4-B5-4B8F39B2(4-B5-51B)4-B5-12B8F4B7F6B4F4B6F2(4-B5-51B)4-B5-5B5C3B3C4BC30B4-B5-2B20C28BC4-B5-BC21D9BD14B3DB4-B5-BCD46ADB11(4-B5-2CD46ADC)4-B5-BCD46ADB4-B5-2CD46ADC2(4-B5-2CD46ADB)21(4-B5-2CD46ADC)4-B5-BC3(D46ADC4-B5-2B)D46ADB4-B5-2BD46ADB4-B5-3B46A2B4-B5-2BD46A2B4-B5-BCD46ADB4-B5-2CD46A2B4-B5-BC7D2(42B4-B5-9C)42B4-B5-B3E47B4-B5-51B4-B5-3B14F34B2(4-B5-51B)4-B5-12B19F6B14F2(4-B5-51B)4-B5-6B2CBC4BC5BC30B4-B5-BC2B18C29B4-B5-BC21D4BD3BD16B2D2(B4-B5-BCD46AD)11(C4-B5-2CD46AD)2(B4-B5-2CD46AD)C2(4-B5-2CD46ADB)18(4-B5-2CD46ADC)4-B5-2CD46ADB4-B5-2CD46ADC4-B5-2CD46ADB4-B5-BCD46ADC4-B5-CBD46ADC2(4-B5-2BD46ADB)4-B5-2B3(D46A2B4-B5-BC)D46A2B4-B5-2C8D41B4-B5-9C42B4-B5-8C43B4-B5-B3E47B4-B5-51B4-B5-B17F33B2(4-B5-51B)4-B5-12B20F5B14F2(4-B5-51B)4-B5-8B3C3BC5BC30B4-B5-5B17C29B4-B5-2B21D2B3D20B2D2(B4-B5-BCD46AD)B7(4-B5-2CD46ADC)4-B5-BCD46ADC4(4-B5-2CD46ADB)3(4-B5-2CD46ADC)2(4-B5-2CD46ADB4(4-B5-2CD46ADC))8(4-B5-2CD46ADC)2(4-B5-2CD46ADB)2(4-B5-BCD46ADC)4-B5-2BD46ADC2(4-B5-2BD46ADB)4-B5-3B46ADB4-B5-3B2(46A2B4-B5-BCD)46A2B4-B5-2C7D42B4-B5-8C43B4-B5-5C46B4-B5-5E46B4-B5-51B4-B5-18F33B2(4-B5-51B)4-B5-13B20F4B14F2(4-B5-51B)4-B5-8B4CB2C3B2C31B4-B5-6B16C29B4-B5-3B28D6BD10BD2B4-B5-3B46A2B4-B5-2BD46ADB4-B5-BC10(D46ADC4-B5-2C)2(D46ADB4-B5-2C)D46ADC4-B5-2CD46ADB2(2(4-B5-2CD46ADC)2(4-B5-2CD46ADB))9(4-B5-2CD46ADC)5(4-B5-2CD46ADB)2(4-B5-BCD46ADC)4-B5-2BD46ADB2(4-B5-3B46A2B)4-B5-2B3(D46A2B4-B5-2C)7D42B4-B5-8C43B4-B5-4C2BC44B4-B5-B3E47B4-B5-51B4-B5-17F34B2(4-B5-51B)4-B5-5B4F5B19F4B14F2(4-B5-51B)4-B5-10B4C4BC32B4-B5-5BCB15C29B4-B5-3B19DB4D10BD13B2(4-B5-2BD46A2B)4-B5-BC2(D46ADB4-B5-2C)3(D46ADC4-B5-2C)D46ADC4-B5-BC4(D46ADC4-B5-2C)4(D46ADB4-B5-2C)D46ADC7(4-B5-2CD46ADB)4-B5-2CD46A2B4-B5-2CD46AB10(C4-B5-2CD46AD)B2(4-B5-2CD46A2B)2(4-B5-BCD46ADB)4-B5-BC3(D46A2B4-B5-2B)3(D46A2B4-B5-2C)4D45B2(4-B5-3C48B)4-B5-2BE48B4-B5-51B4-B5-15F36B2(4-B5-51B)4-B5-4B5F6B18F4B14F2(4-B5-51B)4-B5-11B2C4BC33B4-B5-4B2C2B15C28B4-B5-2B23D12BD13B4-B5-2B2(D46A2B4-B5-BC)2(D46ADB4-B5-2C)2(D46ADC4-B5-2C)2(D46ADC4-B5-BC)2(D46ADC4-B5-2C)D46ADB4-B5-2CD46ADC4-B5-BCD46ADC3(4-B5-2CD46ADB)4-B5-2CD46ADC4-B5-2CD46ADB2(4-B5-2CD46A2B2(4-B5-2CD46ADB))4-B5-2CD46A2B2(4-B5-2CD46ADC)2(4-B5-2CD46ADB)6(4-B5-2CD46ADC)3(4-B5-2CD46A2B)3(4-B5-BCD46A2B)4-B5-2C2(D46A2B4-B5-BC)D46A2B4-B5-2BD46A2B4-B5-BCD46A2B4-B5-2CD48B4-B5-2C49B4-B5-C50B2(4-B5-51B)4-B5-14F25B3F9B2(4-B5-51B)4-B5-4B6F6B17F4B14F2(4-B5-51B)4-B5-10BC40B4-B5-2B3CB18C27B4-B5-2B24D6B2D2B2D13B2(4-B5-BCD46A2B)2(4-B5-BCD46ADB)2(4-B5-2CD46ADC)4-B5-BCD46AB3(C4-B5-2CD46AD)C3(4-B5-BCD46ADB)3(4-B5-2CD46ADB)4-B5-2CD46ADC2(4-B5-2CD46ADB)2(4-B5-2CD46A2B)3(4-B5-2CD46ADB)4-B5-2CD46AB3(C4-B5-2CD46AD)3(B4-B5-2CD46AD)2(C4-B5-2CD46AD)B4-B5-2CD46ADC4-B5-2CD46ADB4-B5-2CD46ABC3(4-B5-2CD46A2B)7(4-B5-BCD46A2B)4-B5-BCD48B4-B5-2C49B3(4-B5-51B)4-B5-12F27B4F8B2(4-B5-51B)4-B5-4B7F7BF6B8F4B14F2(4-B5-51B)4-B5-12BC3B5C30B4-B5-BCB20C9B3C16B4-B5-2B22D7B5D2BD8BD3B2(4-B5-BCD46A2B)2(4-B5-BCD46ADB)4-B5-2CD46ADB4-B5-BCD46ADC4-B5-2CD46ABC4-B5-BCD46A2B4-B5-2CD46ADC5(4-B5-BCD46ADB)4-B5-2CD46ADC4-B5-2CD46A2B3(4-B5-2CD46ADB)2(2(4-B5-2CD46A2B)2(4-B5-2CD46ADB))4-B5-2CD46ADB2(4-B5-2CD46A2B)4-B5-2CD46ADB4-B5-2CD46ADC2(4-B5-2CD46ADB)2(4-B5-2CD46ADC4-B5-2CD46A2B)2(4-B5-2CD46A2B)2(4-B5-BCD46A2B)4-B5-2B2(D46A2B4-B5-BC)D46A2B4-B5-CBD46A2B4-B5-2CDB2D45B4-B5-2C49B3(4-B5-51B)4-B5-11F27B5F8B2(4-B5-51B)4-B5-5B6F16B5F5B14F2(4-B5-51B)4-B5-16B5C30B4-B5-3BC3B15C9B2C18B4-B5-2B22D5B6D3BD12B2(4-B5-BCD46A2B)3(4-B5-BCD46ADB)4-B5-2C7(D46A2B4-B5-BC)2(D46ADB4-B5-BC)15(D46A2B4-B5-2C)8(D46ADB4-B5-2C)D46ADC4(4-B5-2CD46A2B)3(4-B5-BCD46A2B)4-B5-2CD46A2B4-B5-2C4D6BD38B4(4-B5-51B)4-B5-10F28B5F8B2(4-B5-51B)4-B5-6B6F16B3F5B15F4-B5-51B4-B5-18B2E31B4-B5-9BC5B6C30B4-B5-5B17C8BCB2C17B4-B5-2B22D3B9D2(B3D)7B4-B5-2B3(D46A2B4-B5-BC)2(D46ADB4-B5-2C)D46ADB2(4-B5-BCD46A2B)2(4-B5-2CD46A2B)2(4-B5-BCD46A2B)4-B5-2B3(D46A2B4-B5-BC)D46A2B4-B5-2CD46ADB13(4-B5-2CD46A2B)7(4-B5-2CD46ADB)4-B5-2CD46ADC4(4-B5-2CD46A2B)2(4-B5-BCD46A2B)4-B5-2BD46A2B4-B5-BCD46A2B4-B5-2C6D3B3D37B4(4-B5-51B)4-B5-9F30B4F8B2(4-B5-51B)4-B5-7B6F16BF6B8F4B3F4-B5-16B2E33B4-B5-15B5E31B4-B5-5B16C30B4-B5-5B18C5BC4BC2B3C12B4-B5-2B23DB17D8B7(4-B5-BCD46A2B)2(4-B5-2CD46A2B4-B5-BCD46A2B)4-B5-BC2(D46A2B4-B5-2B)4(D46A2B4-B5-BC)14(D46A2B4-B5-2C)4(D46ADB4-B5-2C)7(D46A2B4-B5-2C)2(D46A2B4-B5-BC)2(D46A2B4-B5-2B)DB4D3B2D38B4(4-B5-51B)4-B5-8F43B2(4-B5-51B)4-B5-8B6F21B8F8B4-B5-16B3E32B4-B5-15B6E30B4-B5-7B5CB8C16BC3BC9B4-B5-B2C2B18C4B3C6B4CBC9B4-B5-BC32D2B6DBD7B4(4-B5-2BD46A2B)3(4-B5-BCD46A2B)3(4-B5-2CD46A2B)2(4-B5-BCD46A2B)4(4-B5-2BD46A2B)4-B5-BC9(D46A2B4-B5-2C)3(D46ADB4-B5-2C)4(D46A2B4-B5-2C)2(D46ADB4-B5-2C)6(D46A2B4-B5-2C)4(D46A2B4-B5-BC)2(D46A2B4-B5-2B)3D6BD39B4(4-B5-51B)4-B5-4F47B2(4-B5-51B)4-B5-9B6F20B7F9B4-B5-16B2E33B4-B5-15B5E31B4-B5-10B2C2B8C29B4-B5-B3C2B25C6B4C10B4-B5-BC31D2B8D8B4(4-B5-2BD46A2B)2(4-B5-BCD46A2B)4-B5-2CD46A2B4-B5-BC2(D46A2B4-B5-2C)4(D46A2B4-B5-BC)D46A2B4-B5-2B3(D46A2B4-B5-BC)9(D46A2B4-B5-2C)D46ADB6(4-B5-2CD46A2B)4-B5-2CD46ADB6(4-B5-2CD46A2B)4(4-B5-BCD46A2B)2(4-B5-2BD46A2B)4-B5-2B3D11BD34B7(4-B5-51B)4-B5-9B7F18B7F10B4-B5-51B4-B5-15B4EBE30B4-B5-8B2CBC2B9C3BC24B4-B5-B29C7B5C9B4-B5-BC31D2B7D9B5(4-B5-2BD46A2B)4-B5-BC2(D46A2B4-B5-2B)D46A2B4-B5-BC2(D46A2B4-B5-2C)3(D46A2B4-B5-BC)D46A2B4-B5-2B3(D46A2B4-B5-BC)12(D46A2B4-B5-2C)D46ADB3(4-B5-2CD46A2B)3(4-B5-2CD46ADB)3(4-B5-2CD46A2B)4(4-B5-BCD46A2B)4-B5-2BD3(46A2B4-B5-3B)2D6BD4BD34B7(4-B5-51B)4-B5-9B7F18B6F11B4-B5-51B4-B5-14B4E33B4-B5-11B11C2B3C4BC19B4-B5-BC3B24C7B4C11B4-B5-2B28DB12D8B7(4-B5-2BD46A2B)2(4-B5-BC2(D46A2B4-B5-2C)D46A2B)4(4-B5-BCD46A2B)12(4-B5-2CD46A2B)2(2(4-B5-2CD46ADB)4-B5-2CD46A2B)2(4-B5-2CD46A2B)4-B5-2CD46ADB4-B5-2CD46A2B4-B5-2BD46A2B4-B5-BC2(D46A2B4-B5-2B)D3(46A2B4-B5-3B)46A2B4-B5-7BD43B7(4-B5-51B)4-B5-9B7F17B7F11B4-B5-51B4-B5-14B4E8BE24B4-B5-12B10CB4C24B4-B5-B30C5B2C13B4-B5-BC30D3B8D8B2(4-B5-BCD46A2B)4-B5-2BD46A2B4-B5-BC3(D46A2B4-B5-2B)D46A2B4-B5-BC2(D46A2B4-B5-2C)2(2(D46A2B4-B5-BC)D46A2B4-B5-2C)D46A2B4-B5-BC13(D46A2B4-B5-2C)2(D46ADB4-B5-2C)D46A2B3(4-B5-2CD46ADB)4(4-B5-2CD46A2B)2(4-B5-BCD46A2B)4-B5-2BD4(46A2B4-B5-3B)46A2B4-B5-7BD43B4(4-B5-51B)4-B5-39B3F9B2(4-B5-51B)4-B5-2F7B7F17B6F12B4-B5-51B4-B5-13B2EB2E7BE25B4-B5-2B2C2BC4B7CB2C4BC25B4-B5-B3CB23C2B2C4B2C13B4-B5-BC40D9B2(4-B5-BCD46A2B)4-B5-2BD46A2B4-B5-CB2(D46A2B4-B5-2B)D46A2B4-B5-BC2(D46A2B4-B5-2C)3(D46A2B4-B5-BC)2(D46A2B4-B5-2C)2(D46A2B4-B5-BC)2(D46A2B4-B5-2C)D46A2B4-B5-BC11(D46A2B4-B5-2C)D46ADB9(4-B5-2CD46A2B)4-B5-BC2(D46A2B4-B5-2B)D4(46A2B4-B5-3B)46A2B5(4-B5-51B)4-B5-39B3F9B2(4-B5-51B)4-B5-2F7B7F18B4F13B4-B5-51B4-B5-17BE7BE4B2E19B4-B5-4CB3C3B8C2B5C7BC17B4-B5-28CB3CB5C13B4-B5-2C38D4BD6B4-B5-2C3(D46A2B4-B5-BC)2(D46A2B4-B5-2B)2(D46A2B4-B5-BC4(D46A2B4-B5-2C))22(D46A2B4-B5-2C)2(D46A2B4-B5-BC)2(D46A2B4-B5-2B)D4(46A2B4-B5-3B)46A2B5(4-B5-51B)4-B5-39B2F10B2(4-B5-51B)4-B5-2F7B7F18B2F10B5F4-B5-51B4-B5-2E28B3E18B4-B5-8C4B7C2BC2B4C2B5C16B4-B5-38C13B4-B5-2C39D5BD4B2(4-B5-2CD46A2B)4-B5-BCD46A2B4-B5-2B3(D46A2B4-B5-BC)D46A2B4-B5-2CD46A2B4-B5-BC27(D46A2B4-B5-2C)4(D46A2B4-B5-BC)D46A2B4-B5-2BD3(46A2B4-B5-3B)46A2B4-B5-2BD46A2B4-B5-3B46A2B8(4-B5-51B)4-B5-2F7B6F29B7F4-B5-51B4-B5-2E2B2E9B3E14BE18B4-B5-8C3B11C2B6CB4C16B4-B5-39C12B4-B5-2C39D5B2D3B5(4-B5-2CD46A2B)4-B5-BC2(D46A2B4-B5-2C)2(D46A2B4-B5-BC)27(D46A2B4-B5-2C)2(D46A2B4-B5-BC)D46A2B4-B5-2BD46A2B4-B5-BC3(D46A2B4-B5-2B)D2(46A2B4-B5-3B)46A2B8(4-B5-51B)4-B5-F42B8F4-B5-16BE34B4-B5-6E6B8E31B4-B5-8CB17CB7C17B4-B5-39C12B4-B5-2C40D2B2DB2D9(2B4-B5-2CD46A)2(2B4-B5-BC2(D46A2B4-B5-2C)D46A)22(2B4-B5-2CD46A)2(2B4-B5-BCD46A)5(2B4-B5-2BD46A)2(2B4-B5-3B46A)2B8(4-B5-51B)4-B5-F41B9F4-B5-16B5E30B4-B5-6E4BEB10E29B4-B5-25C2B7C17B4-B5-39CBC10B4-B5-2C40D2B2D5B9(4-B5-2CD46A2B)4(4-B5-BCD46A2B)25(4-B5-2CD46A2B)3(4-B5-BCD46A2B)4-B5-2B2(D46A2B4-B5-BC)D2(46A2B4-B5-3B)46A2B8(4-B5-51B)4-B5-18B2F22B9F4-B5-15B2EB4E29B4-B5-B5E2B15E28B4-B5-30C21B4-B5-39C12B4-B5-2C39D4BD5B9(4-B5-2CD46A2B)4(4-B5-BCD46A2B)24(4-B5-2CD46A2B)4-B5-BCD46A2B4-B5-2C3(D46A2B4-B5-BC)2(D46A2B4-B5-2B)D2(46A2B4-B5-3B)46A2B8(4-B5-51B)4-B5-14B2G2BF2GF19B10F4-B5-10B12E29B4-B5-6EB18E26B4-B5-30C21B4-B5-38C13B4-B5-2C40D9B11(4-B5-2CD46A2B)4-B5-BC28(D46A2B4-B5-2C)2(D46A2B4-B5-BC)D46A2B4-B5-2BD3(46A2B4-B5-3B)46A2B5(4-B5-51B)4-B5-B5F8B6F31B2(4-B5-51B)4-B5-14BG3B4G19B6F2B2F4-B5-EBE7B14E27B4-B5-25EB3E22B4-B5-30C21B4-B5-31CB4C15B4-B5-2C40D6B2DB39(4-B5-2CD46A2B)4(4-B5-BCD46A2B)3(4-B5-3B46A2B)4-B5-9BD41B4(4-B5-51B)4-B5-9F2B11F29B2(4-B5-51B)4-B5-G7BG8B6G17B6F3B2F4-B5-3E3B19E26B4-B5-28E23B4-B5-30C21B4-B5-31C2BC14BC2B4-B5-2C39D5B4DB39(4-B5-2CD46A2B)4(4-B5-BCD46A2B)4-B5-2BD2(46A2B4-B5-3B)46A2B4-B5-9BD41B4(4-B5-51B)4-B5-23F28B2(4-B5-51B)4-B5-2G7B3F4BGB7G15B6F3B2F4-B5-4EB20E26B4-B5-29E22B4-B5-29C22B4-B5-31C18BCB4-B5-2C39DBD2B5D2(B4-B5-2CD46AD)B5(4-B5-2CD46A2B)2(4-B5-2CD46ADB)4(4-B5-2CD46A2B)2(4-B5-BCD46A2B)22(4-B5-2CD46A2B)4-B5-BCD46A2B4-B5-2C4(D46A2B4-B5-BC)D46A2B4-B5-2BD2(46A2B4-B5-3B)46A2B4-B5-9BD41B4(4-B5-51B)4-B5-24F27B2(4-B5-51B)4-B5-3G5BF4GB2G2B3F5G14B6F3B2F4-B5-4E4B17E26B4-B5-29E22B4-B5-29C22B4-B5-30C20BC4-B5-2C32DB3D2(2BD)B5D2(C4-B5-2CD46ADB4-B5-2CD46AD)B9(4-B5-2CD46A2B)4-B5-BC24(D46A2B4-B5-2C)5(D46A2B4-B5-BC)2(D46A2B4-B5-2B)D46A2B4-B5-3B46A2B4-B5-7B2D42B4(4-B5-51B)4-B5-25F26B2(4-B5-51B)4-B5-4G4BF10GF5G14B7F3B2F4-B5-5E3B17E26B4-B5-28E23B4-B5-28C23B4-B5-30C19B2C4-B5-2C32D2BD3B2(D2B)4D2(C4-B5-2CD46AD)B2(4-B5-2CD46ADC)3(4-B5-2CD46ADB)31(4-B5-2CD46A2B)4-B5-BC3(D46A2B4-B5-2C)3(D46A2B4-B5-BC)D46A2B4-B5-3B46A2B4-B5-7B2D42B4(4-B5-51B)4-B5-12F5B9F25B2(4-B5-51B)4-B5-3G4B2F10GF5G14B8F2B2F4-B5-5E4B16E26B4-B5-5EBEB18EBE23B4-B5-28C23B4-B5-29C20B2C4-B5-2C28D15B5D7(C4-B5-2CD46AD)B35(4-B5-2CD46A2B)4(4-B5-2BD46A2B)4-B5-7B3D41B4(4-B5-51B)4-B5-12F6B10F23B2(4-B5-51B)4-B5-3G4B3F9GF2GF17B11F4-B5-5E5B15E26B4-B5-26E25B4-B5-28C23B4-B5-29C22B4-B5-2C28D15B2(2DB)4-B5-2CD46ADB5(4-B5-2CD46ADC)4-B5-2CD46ADB35(4-B5-2CD46A2B)4-B5-BC2(D46A2B4-B5-2B)D46A2B4-B5-3B46A2B4-B5-2BD3B4D41B4-B5-BC49B3(4-B5-51B)4-B5-11F8B10F22B2(4-B5-51B)4-B5-2GBG2B4FGF9GBG18B10F4-B5-7E3BEB14E25B4-B5-27E24B4-B5-29C22B4-B5-30C21B4-B5-2C29D5BD7B2D5B2(4-B5-2CD46ADB)3(4-B5-2CD46ADC)2(4-B5-2CD46ADB)35(4-B5-2CD46A2B)2(4-B5-BCD46A2B4-B5-2BD46A2B)4-B5-2B4DB4D40B4-B5-B5C45B4-B5-2C3BC45B2(4-B5-51B)4-B5-10F9B10F22B2(4-B5-51B)4-B5-4G2B4FG2B11G18B9F4-B5-7E6B12E26B4-B5-9EB18E23B4-B5-28C23B4-B5-29C22B4-B5-2C27D5BD16B7(4-B5-2CD46ADB)35(4-B5-2CD46A2B)4(4-B5-BCD46A2B)4-B5-BC9D40B4-B5-B7C43B4-B5-6C45B2(4-B5-51B)4-B5-9F11B8F23B2(4-B5-51B)4-B5-5G2B3F3B11G19B8F4-B5-6E5BEB13E25B4-B5-7E2B19E23B4-B5-29C22B4-B5-30C21B4-B5-2C28D2B3D16B4-B5-2CD46A2B5(4-B5-2CD46ADB)36(4-B5-2CD46A2B)4(4-B5-BCD46A2B)4-B5-BC11D38B4-B5-8CB2C40B4-B5-7C44B4-B5-2(BE)47B4-B5-51B4-B5-3B2F16B5F25B2(4-B5-51B)4-B5-5G8B9G23B6F4-B5-7E5B13E26B4-B5-27E24B4-B5-29C22B4-B5-30C21B4-B5-2C28D21B44(4-B5-2CD46A2B)2(4-B5-BCD46A2B)4-B5-BC12DBD35B4-B5-7C2B2C40B4-B5-7C44B4-B5-3BEBE45B4-B5-51B4-B5-23BF27B2(4-B5-51B)4-B5-3G7BG2B9G24B5F4-B5-23E28B4-B5-26E25B4-B5-28C23B4-B5-30C21B4-B5-2C29D20B46(4-B5-2CD46A2B)4-B5-2C13D36B4-B5-10CBC39B4-B5-7C44B4-B5-B3E47B4(4-B5-51B)4-B5-7B14G26B4F4-B5-EB20E29B4-B5-24E27B4-B5-26C25B4-B5-29C22B4-B5-2C28D21B40(4-B5-2CD46A2B)4-B5-BC6(D46A2B4-B5-2C)13D36B4-B5-10C41B4-B5-7C3BC40B4-B5-B3E47B4(4-B5-51B)4-B5-6B14G29B2F4-B5-5B15E31B4-B5-21E30B4-B5-25C26B4-B5-29C22B4-B5-2C28D21B40(4-B5-2CD46A2B)2(4-B5-BCD46A2B)4(4-B5-2CD46A2B)4-B5-2C9DBD38B4-B5-11C40B4-B5-9C42B4-B5-B2E48B4-B5-51B4-B5-9B7F35B2(4-B5-51B)4-B5-8B11G32B4-B5-3B2EB13E32B4-B5-20E31B4-B5-21C2BC27B4-B5-26CBC23B4-B5-2C27D22B40(4-B5-2CD46A2B)4(4-B5-BCD46A2B)2(4-B5-2CD46A2B)4-B5-2C10D39B2(4-B5-11C40B)4-B5-B2E48B4-B5-51B4-B5-6B12F33B2(4-B5-51B)4-B5-4B3G2B4G4BG16B3F14B4-B5-3BEB14E32B4-B5-19E32B4-B5-20C3BC27B4-B5-26CBC23B4-B5-2C27D22B39(4-B5-2CD46A2B)7(4-B5-BCD46A2B)4-B5-2C11D6BD31B4-B5-B11C39B4-B5-B10C40B4-B5-B2EBE46B4-B5-51B4-B5-4B16F31B2(4-B5-51B)4-B5-2B4G3B3G22B3F14B4-B5-B5EB8E36B4-B5-B17E33B4-B5-20C2(BC)27B4-B5-24C27B2(4-B5-2C27D22B)7(4-B5-2C28D21B)4-B5-2C29D20B3(4-B5-2C31D18B)2(4-B5-2C25D2B5D17B)2(4-B5-2C32D17B)4-B5-2C31D18B4-B5-2C30D7BDBD9B2(4-B5-2C28D21B)4-B5-2C27D8BD13B4-B5-2C26D9B2D12B4-B5-2C26D10B2D11B4-B5-2C25D24B3(4-B5-2C24D25B)4-B5-2C22DB2D24B3(4-B5-2C22D27B)4-B5-2C18D31B4-B5-2C19D30B2(4-B5-2C18D31B)4-B5-2C17D3BD28B4(4-B5-2C17D32B)2(4-B5-BC16D33B)2(4-B5-BC17D32B)4-B5-BC18D31B4-B5-BC17D32B4-B5-BC12D2B3D32B4-B5-B11C39B4-B5-11C40B4-B5-3BE4B2E41B4-B5-51B4-B5-3B18F30B2(4-B5-51B)4-B5-5B4G13B3F26B4-B5-2BE2B9E37B4-B5-B17E33B4-B5-18C4BC28B4-B5-24C27B4-B5-23C2B2C24B4-B5-24CB4C22B4-B5-22C3B3C2(23B4-B5-28C)23B4-B5-25C2BC23B4-B5-28C23B4-B5-26CBC2(23B4-B5-28C)23B4-B5-29C22B4-B5-26C25B4-B5-27C3B2C19B4-B5-26C4B2(C20B4-B5-27C3B)2(2C19B4-B5-28C2B)2C19B4-B5-28CB2C20B4-B5-29C22B4-B5-28C23B3(4-B5-27C24B)4-B5-26C25B2(4-B5-23C28B)4-B5-24C27B2(4-B5-22C29B)4-B5-20CBC29B4-B5-20C31B2(4-B5-18C33B)4-B5-17CBC32B4-B5-17C34B4-B5-19C32B2(4-B5-18C33B)4-B5-17C2(34B4-B5-B16C)34B4-B5-17C34B4-B5-C2B14C34B4-B5-BCB14C34B4-B5-B15C35B4-B5-B13C37B4-B5-B12C38B4-B5-12C39B4-B5-10C41B4-B5-2B3E46B4-B5-3BE47B4-B5-3B19F29B2(4-B5-51B)4-B5-3B7G11B6F24B4-B5-2B11E38B4-B5-16E35B2(4-B5-18C33B)4-B5-20CBC29B4-B5-20C31B2(4-B5-21C30B)3(4-B5-23C28B)4-B5-5CB17C28B4-B5-5CB18C27B3(4-B5-23C28B)4-B5-24C27B4-B5-26C25B5(4-B5-27C24B)4-B5-28C23B4-B5-26CBC23B4-B5-27C24B2(4-B5-24C27B)2(4-B5-22C29B)4-B5-17C2B3C29B4-B5-16CB6C28B4-B5-17CB4C29B4-B5-15C3BCB2C29B4-B5-16C5BC29B4-B5-16C35B2(4-B5-15C36B)2(4-B5-16C35B)2(4-B5-17C34B)4-B5-16C35B2(4-B5-15C36B)4-B5-2B13C36B4-B5-2(CB)11C36B4-B5-3B11C37B4-B5-3B7C2(BC)37B4-B5-2B8CBC39B4-B5-10C41B4-B5-9C42B4-B5-10C41B4-B5-6CB3C41B4-B5-2B4EB2E42B4-B5-3B2E3BE42B4-B5-3B20F28B2(4-B5-51B)4-B5-2B8G10B7F24B4-B5-2B11E38B4-B5-18E33B4-B5-2EB15E33B4-B5-2E3B13E33B4-B5-18E33B3(4-B5-19E32B)4-B5-20E31B4-B5-5EB15E30B4-B5-2E2B16E31B4-B5-7B14E30B4-B5-7B15E29B4-B5-7B14E30B4-B5-EB2EB16E30B2(4-B5-2B21E28B)4-B5-12EB11E27B4-B5-25E26B4-B5-12EB12E26B4-B5-26E25B4-B5-14EB12E24B2(4-B5-26E25B)4-B5-27E24B4-B5-25E26B4-B5-24E27B4-B5-23E28B4-B5-18E2B3E28B4-B5-17E34B2(4-B5-15E36B)4-B5-14E37B4-B5-B13E37B4-B5-2B13E36B4-B5-2B11E38B4-B5-6EB4E40B4-B5-B6EB4E39B4-B5-B11E39B4-B5-12E39B2(4-B5-16E35B)2(4-B5-15E36B)4-B5-2B12E37B4-B5-B12E38B4-B5-3B10E38B4-B5-5B4E2BE39B4-B5-3B6E42B4-B5-3B3E2B2E41B4-B5-BE2BE3BE42B4-B5-5B3E43B4-B5-51B4-B5-2BE4B2E42B4-B5-2B8E41B4-B5-3B6E42B4-B5-3BFG19F27B2(4-B5-51B)4-B5-2BGB6G10B7F24B4-B5-B12E38B4-B5-2B8E41B4-B5-6B5EB3E2BE33B4-B5-6B9E36B4-B5-E6B8E36B4-B5-2E4B9E36B4-B5-5B6EB3EB2E33B4-B5-6B5E2B5E33B4-B5-6B12E33B4-B5-6B5EB7E32B4-B5-7B13E31B4-B5-8B11E32B4-B5-7B12E32B4-B5-6B13E32B4-B5-7B5E2B6E31B4-B5-4B8E2B7E30B4-B5-4B9EB5EB2E29B4-B5-2BEB6E6B8E27B4-B5-7EB2E3B11E27B4-B5-9EBE2B11E27B4-B5-14E2B10E25B4-B5-13E4B2EB6E25B4-B5-13E4B2E2B2(5E25B4-B5-14E3B3EB)4E26B4-B5-17EB6E27B4-B5-14E2B7E28B4-B5-14E2B3E2B2E28B4-B5-16E35B2(4-B5-15E36B)4-B5-13E38B4-B5-BEB10E38B2(4-B5-3B9E39B)4-B5-3B8E40B4-B5-4BEB4E41B4-B5-2BEBE3B2E41B4-B5-2BE2B5EBE39B4-B5-B10E40B4-B5-3EB8EBE37B4-B5-3E4B8E36B4-B5-2E4B8E37B4-B5-5B2EB5E38B4-B5-6B6E39B4-B5-6B2E2B2E39B4-B5-4BE6BE39B4-B5-4BE46B4-B5-5BE45B6(4-B5-51B)4-B5-3B3EB2E42B4-B5-4B2G18F19BF7B2(4-B5-51B)4-B5-5B5G10B6F25B4-B5-6B3G10B15F17B4-B5-7B2G8B18F16B4-B5-7B4G7B18F15B4-B5-7B3G9B19F13B4-B5-7B3G4B2G4B18F13B4-B5-6B4G4BG5B19F12B4-B5-6B4G3BG7B19FB8F2B4-B5-6B3G13B24F3B2F4-B5-7B4G13B19F6B2F4-B5-7B3G5BG13B14F7BF4-B5-7B3G5B2G13B12F8BF4-B5-8B2G3B5G13B11F9B4-B5-9BG3B5G14B8F11B4-B5-7B3GB4FG2F16B4F13B4-B5-8BG2B9F31B4-B5-6B3G2B6FG2F31B4-B5-9B2GB4F3G15B3F14B4-B5-3F13B3GBG13B3F14B4-B5-8F8B3GB4G27B4-B5-F5G3F2G10B3G27B4-B5-11G9B4G27B4-B5-12G9B4G26B4-B5-12G9B3G24B3F4-B5-12G10B2G20B7F4-B5-13G9B2G9B5F6B7F4-B5-11GB2G9BG8B6F7BF5B4-B5-14G18B5F14B4-B5-13G19B2F17B4-B5-13G38B4-B5-B13G37B4-B5-B3G2B8G37B4-B5-4B9G38B4-B5-3F2B7G11B2F26B4-B5-4FB7G8B8F23B4-B5-B3FGB5G9B9F22B4-B5-4B5G12B9F21B4-B5-6B3G17B6F19B4-B5-5B4G17B7F9B9F4-B5-7B2G9B4F2B10F7B10F4-B5-7B2G8B18F5B11F4-B5-8BG14B11F5B12F4-B5-2G28B3F5B13F4-B5-9B4G11BF13B13F4-B5-9B4F9B6F10B9F3BF4-B5-22B9F8B6F6B4-B5-23B8F19BF4-B5-26B5F18B2F4-B5-11B2F14B3F21B4-B5-27B3F21B4-B5-39B6F6B4-B5-15BF19B16F4-B5-15B6F12B10F4B4F4-B5-16B4F30BF4-B5-17B3F31B4-B5-51B4-B5-6B6F31B2F6B4-B5-5BFG18F26B4-B5-51B4-B3660-
