size = 11 7 11
shape = cylinder-y
scale = 0.025 0.005 0.025
rotation = 60 0 -15
position = 0 0.7 0
clamp = y
ao = 5 1030 180

material type = normal, lighting = smooth, side = back
  colors = Shell:#FFF
  
material lighting = both, roughness = 0.25, metalness = 1
  colors = A:#060 B:#030
  
// An extra surface is created because the concave shape give an ugly looking shell
material type = basic, opacity = 0.01, deform = 2, shell = Shell -0.4
  colors = D:#FFF  
  
voxels
DDDDDDDDDDD DDDDDDDDDDD DDDDDDDDDDD DDDDDDDDDDD DDDDDDDDDDD DDDDDDDDDDD DDDDDDDDDDD 
DDDDDDDDDDD DAAAAAAAAAD DAAAAAAAAAD DAAAAAAAAAD DAAAAAAAAAD DAAAAAAAAAD DDDDDDDDDDD  
DDDDDDDDDDD DADDDDDDDAD DABBBBBBBAD DABBBBBBBAD DABBBBBBBAD DADDDDDDDAD DDDDDDDDDDD 
DDDDDDDDDDD DADAAAAADAD DABBBBBBBAD DABBBBBBBAD DABBBBBBBAD DADAAAAADAD DDDDDDDDDDD 
DDDDDDDDDDD DADDDDDADAD DABBBBBBBAD DABBBBBBBAD DABBBBBBBAD DADADDDDDAD DDDDDDDDDDD 
DDDDDDDDDDD DADAAAAADAD DABBBBBBBAD DABBBBBBBAD DABBBBBBBAD DADAAAAADAD DDDDDDDDDDD 
DDDDDDDDDDD DADADDDDDAD DABBBBBBBAD DABBBBBBBAD DABBBBBBBAD DADDDDDADAD DDDDDDDDDDD 
DDDDDDDDDDD DADAAAAADAD DABBBBBBBAD DABBBBBBBAD DABBBBBBBAD DADAAAAADAD DDDDDDDDDDD 
DDDDDDDDDDD DADDDDDDDAD DABBBBBBBAD DABBBBBBBAD DABBBBBBBAD DADDDDDDDAD DDDDDDDDDDD 
DDDDDDDDDDD DAAAAAAAAAD DAAAAAAAAAD DAAAAAAAAAD DAAAAAAAAAD DAAAAAAAAAD DDDDDDDDDDD 
DDDDDDDDDDD DDDDDDDDDDD DDDDDDDDDDD DDDDDDDDDDD DDDDDDDDDDD DDDDDDDDDDD DDDDDDDDDDD