model
name = main
revision = 2
size = 61 60 60
shape = sphere
scale = 0.017
origin = -y
shell = Outline 0.25
material lighting = smooth, fade = true, opacity = 0.35, deform = 3 1
  colors = B:#06F
material lighting = smooth, deform = 3 1, scatter = 0.5
  colors = F:#CCC
material deform = 3 1, scatter = 0.4
  colors = G:#FFF
material deform = 3 1, scatter = 0.3
  colors = E:#888
material lighting = smooth, fade = true, deform = 3 1, scatter = 0.2
  colors = C:#482 D:#6A4
material lighting = smooth, roughness = 0, deform = 3 1, scatter = 0.1
  colors = A:#04F
material type = basic, lighting = smooth, roughness = 0, refractionRatio = 1, side = back
  colors = Outline:#000
voxels
61(2-57B-B)2-11F46B-B2-17F40B-B2-2B14F9B12F7B5F8B-B2-7B4F13B13F6B7F7B-B2-24B12F6B9F6B-B2-43B9F5B-B2-41BG2B7F2G4F-B2-42B2G2B5FG5F-B2-40B3G5B3FG5F-B2-24BF14B4G14B-B2-22B4F8B4FB3G15B-B2-22B6F7B4F4G14B-B2-2BG20B5F10B5G9BG4B-B2-2B2G8B3F8B4F12B4G14B-B2-3B2G8B12F15B3G11BGBG-B2-3B3G7B12F15B2G11BFB2G-B2-F6G6B2FG9F12B4G12BG2BG-B2-16G4B4G2F10B3G2F16B-B2-3B13G3B5G3F9B7F7B7G-B2-B2GF20G2F9B10F5B7G-B2-BG2F16G2B3G2F8B11F4B7G-B2-G2BF5B3GB3G5BFG5F9B6F9B5G-B2-9B2G10B6F25B5G-B2-22B3F28B4G-B2-14BG38B4G-B2-11BG42B3G-B2-5F5BG26B5F11B4G-B2-5F5BG43B3G-B2-6F51B-B2-B7F49B-B2-2B8F36B4F7B-B2-2B9F37B5F4B-B2-B9F40B6FB-B2-8F43B5FB-B2-7F25B3F17B4FB-B2-6F25B8F18B-B2-6F13B5F8B8F17B-B2-6F14B5F32B-B2-6F15B5F31B-B2-7F14B6F20B6F4B-B2-7F15B5F17B12FB-B2-7F16B5F15B13FB-B2-7F17B4F14B13F2B-B2-3FG4F16B5F12B13F3B-B2-3B6F15B5F12B11F5B-B2-5B5F14B3F14B6F10B-B2-F5B6F45B2(-B2-2F55B)-B2-24B2F27B2F2B-B2-46B10FB-B2-45B12F-B2-44B13F-B2-21B6F17B13F-B2-19B9F16B13F-B2-18B11F28B-B2-18B14F25B-B2-27B6F24B2(-B2-57B)-B2-7F50B-B2-F51B3E2B-B2-50B5E2B-B2-47BE2B2E5B-B2-49BE2BE4B-B2-48B5E4B-B2-40BE2BEBE3B5E3B-B2-BE37B3EB2E4B4E4B-B2-B2E35B6E5B3EBE3B-B2-B2E36B6E4B4E4B-B2-B2E34B8E7BE4B-B2-B2E32B8E14B-B2-B3E31BE2B5E9BE4B-B2-B6E10BE6B3E9B9E7B3E2B-B2-B6EBE13B5E9B9E7B4EB-B2-G7E12B6E9B10E8B4E-B2-G8E2B16E8B11E7B4E-B2-G25E9B7E2B2E5B6E-B2-G28E7B4E2B4E4B7E-B2-G27E22B7E-B2-B19EB6E23B7E-B2-B17E3(B2E)23B7E-B2-2B3E3B5EB8E3B2E24B6E-B2-B3E4B11E32B6E-B2-2BE5B11E5BE26B6E-B2-FE6B7EB5E31B5E-B2-F5B7EB9E29B5E-B2-F7B5EBE2B6E31B3E-B2-G7B4E6BE36B2E-B2-56BE-B2-19BE37B2(-B2-57B)7(-B2-F56B)-B2-FE55B2(-B2-F3E53B)-B2-FB3E52B-B2-3BE53B-B2-57B3(-B2-F56B)8(-B2-57B)-B2-17B16F24B2(-B2-57B)-B2-5F48B2F2B-B2-F51B2E3B-B2-26BE16BE4B8EB-B2-40BEB13E2B-B2-40BEB12E3B-B2-41BE2B3EB6E3B-B2-2BE34B5EB2EBEB6E3B-B2-B2E33B9E4B6E2B-B2-2B2E31B2(9E2B)-B2-B3E20BE9B11E2B8E2B-B2-B4E14B2E13B11E4B5E3B-B2-B6E7B2E3BE2B2E11B12E3BE2B2E2B-B2-B7E3BE2B12E3BE5B11E4B2EB2E2B-B2-B8EB20E4B13E4B5EB-B2-F18EB7E7B15E3B4EB-B2-G9E2B15E7B15E2B6E-B2-G27E6B16E3B4E-B2-G28E3B16EBEB6E-B2-G29E3B24E-B2-G30E2B24E-B2-B30EB6E2BEB15E-B2-F30E3B2E5B16E-B2-FB27E5B2E8BE4B7EB-B2-G29E3B2E7B4E4B7E-B2-F4EB19E2B3E13B3E4B7E-B2-F25E19BE3BEB6E-B2-F2EB22E23B8E-B2-F2E2B19E26BE2B4E-B2-G3E2B18E26BE4B2E-B2-2B2E2B4E5B8EBE30BEB-B2-B3E2(2BE)6B6EBE33B-B2-2BE4B2E8B6EBE29BE2B-B2-18B5E34B-B2-18B2EB2E34B-B2-FBE15BE38B-B2-F52BE3B-B2-F16BE34B2E3B2(-B2-F56B)-B2-FBE51BE2B-B2-FB2E53B-B2-F56B2(-B2-FB3E52B)2(-B2-2B3EBE50B)-B2-FB4EBE49B-B2-FB3E2BE49B-B2-F6B2E48B-B2-57B2(-B2-6B2E49B)-B2-9BE47B-B2-5BE2B2E47B-B2-5BE2BE48B-B2-5B2E50B-B2-57B-B2-17B16F24B2(-B2-57B)-B2-4F49B3FB-B2-F49BE2BE3B-B2-25BE16BEBE2B8E2B-B2-16BC8B3C10B17C2B-B2-15B2C9B3C9B17C2B-B2-15B2C7B5C5B21C2B-B2-3BC10BC8B3CBC6B21C2B-B2-2BE3C17B2C8B13C2B7C2B-B2-2BE5C7B2(CB)2CB3C8B22CEB-B2-B2E7C4B12C7B22C2B-B2-B2E6C4B13C2BC5B21C2B-B2-B2E24C2BC4B21C2B-B2-B2E28C2B16CB5C2B-B2-F2E46C2B4CEB-B2-G2E48CB3CEB-B2-F2E52C2E-B2-F2E27CB24C2E-B2-B2E52CEB2(-B2-G2E52C2E)-B2-F2E52C2E-B2-F2E52CEB-B2-F2E28CB6CB16CEB-B2-FBE34C2B16C2E-B2-G2E28CB5C2B16CEB-B2-G2E24C5B4C4B15CEB-B2-G2E23C15B14C2E-B2-F2E23C18B11C2E-B2-2BE22C21B9CEB-B2-2BE7CB15C25BC2BCEB-B2-2BE6C6B10C3B3C23BCEB-B2-2BE6C7B9C3B2C18BC4B2C2B-B2-2BE6C8B8C27B3C2B-B2-2BE5C7BCB8C18BC7B4C2B-B2-FBECBC9B4CBCB5C25B3C2B-B2-F13B6C2BC29B3C2B-B2-F2B3C8B3C2(B2C)19BC8B4C2B-B2-F2BC10B3CBC2B2C19B2C7B4C2B-B2-F2BC10B3C3B2C20B2C7BCB2C2B-B2-F2BC11B2C37BC2B-B2-F53BC2B-B2-F2B2CBC50B2(-B2-FBE5C49B)2(-B2-3B5C49B)-B2-FBE7C47B-B2-F2BCB4C48B-B2-F4B2CBC48B-B2-5BCBC9BC39B-B2-5B4C7BC40B-B2-5B5C7BC39B-B2-4B6C47B-B2-3B7C3BC43B-B2-3B6C3BC44B-B2-5B2E50B-B2-57B-B2-17B16F11B4F9B2(-B2-57B)-B2-4F49B3FB-B2-F56B-B2-45BE2(2B2E)BEB-B2-17BC7B3CBC10B15C2B-B2-12B7C4B8C3BCB19C2B-B2-13B5C5B8C2B21C3B-B2-4B2C7B5C5B7C3B22C2B-B2-3B5C2BC2B16C4B22C2B-B2-2BE23CB3C2B23C2B-B2-B2E52C2B2(-B2-B2E51C3B)-B2-B2E52C2B2(-B2-G2E52CEB)-B2-F2E52C2E-B2-G2(2E52CEB-B2-B)2E52C2B5(-B2-G2E52CEB)-B2-FBE2(52CEB-B2-F2E)24C6B22CEB-B2-2BE25C6B8C2B11C2B-B2-2BE24CBC4BCB4CBC3B11CEB-B2-2BE26CB2C2B3C2B2CBC4B5CBC3B-B2-3B6CB23C7B2C4B8C3B-B2-2BE7CBC4B17CBC8B11C3B-B2-B2E9C4B15CB2C9B12C2B-B2-B2E9C3B14C2B5C6B4CBC3B4C2B-B2-2BE7CB18C4B2(4C5B)4C2B-B2-FBE5C5B14CBC7B2C4B3C4B6C2B-B2-FBE5C3B15C16B2C7B4C2B-B2-F2B5C3B12C19B3C5B5C2B-B2-F2B3C6B11C19B3C5B4C3B-B2-F2BC11B2CB4C20B4C4B4C3B-B2-F13B3C3BC29B4C3B-B2-F5B2C7BC5BC29B3C3B-B2-F2B6C43B2C3B-B2-F2B6C7BCBC38B2(-B2-3B6C48B)-B2-F2B7C47B-B2-F2B7C4B2C41B-B2-F3B7C3B4C39B-B2-4B5C4B6C38B-B2-4B5C2B8C38B-B2-4B7CB8C37B-B2-3B8CB7C38B-B2-3B8CB5C40B-B2-2BE6C48B-B2-2B5EBE48B-B2-57B-B2-18B14F10B7F8B2(-B2-57B)-B2-3F50B2F2B-B2-F56B-B2-57B-B2-17BC6B2C2(BC)13B2C2B8C2B-B2-14B4C5B8C7B17C2B-B2-5B2D3BDB7D3B31D2(C3B-B2-4BC48D)C3B-B2-3B2(2C48DC3B-B2-2BE)2(2C48DC3B-B2-B2E)2(2C48D2C2B-B2-F2E)2C48D2CEB-B2-G2E2C48D2CEB-B2-F2E2C48D2CEB-B2-B2E2C48D2C2B-B2-B2E2C48DC3B-B2-B2E2C48D2C2B2(-B2-G2E2C48D2CEB-B2-F2E2C48D2CEB)2(-B2-FBE2C48D2CEB)-B2-F2E2C48DC3B-B2-2BE2C48DC3B-B2-B2E2C48D4B-B2-B2E2C48DC3B-B2-BEB2C37DB10DC3B-B2-2BE2C36D2B10D2C2B-B2-2BE2C36DB11D2C2B-B2-B2E2C48D2C2B-B2-2BE2C41D3B4D2C2B-B2-FBE2C25D4B12D2B5D2C2B-B2-FBE2C22DBD4BD2BD3B5D4B4D2C2B-B2-F2B2C4D2B14D15B5D4B4D2C2B-B2-F2B2C19D17B4D2BD2B3D2C2B-B2-F4B4D2B14D16B4DB2D2B3D2C2B-B2-F4B4DB15D22BDB4D2C2B-B2-F4BDB2DB15D25B3D2C2B-B2-F3BC7DB11D27B2DC3B-B2-4BC5D4B5D2B5D31B-B2-4BC6D3B5D3B4D31B-B2-3B2C5D3B6D3B4D31B-B2-F2B2C6D2B5D5B3D31B-B2-F3BC5D2B7D38B-B2-F4B14D38B-B2-5B14DBD36B-B2-4BC16D36B-B2-4BC15D37B-B2-4BC14D38B-B2-2BE7C5B2C40B-B2-2BE6C48B-B2-2B5EBE48B-B2-57B-B2-23B9F10B7F8B2(-B2-57B)-B2-3F50B2F2B2(-B2-F56B)-B2-24B6C13BC7B4C2B-B2-4BC6BC2B4C5B9C6B8C2B7C2B-B2-5B48D2C2B-B2-4BCD46ADC3B-B2-3B2(2CD46ADC3B-B2-2BE)2CD46ADC3B-B2-B2E2CD46AD2C2B-B2-B2E2CD46ADC3B-B2-B2E2CD46AD2C2B-B2-F2E2CD46ADC3B2(-B2-F2E2CD46AD2C2B)-B2-F2E2CD46AD2CEB2(-B2-B2E2CD46AD2C2B)-B2-B2E2CD46ADC3B2(-B2-F2E2CD46AD2C2B)-B2-B2E2(2CD46AD2C2B-B2-FBE)2CD46ADC3B-B2-FBE2CD46ADC3B-B2-F2E2CD46ADC3B-B2-B2E2CD46AD4B2(-B2-B2E2CD46ADC3B)3(-B2-2BE2CD46AD2C2B)-B2-B2E2CD46AD2C2B-B2-2BE2CD46ADC3B-B2-B2E2(2CD46AD2C2B-B2-FBE)2CD46AD2CEB-B2-FBE2CD46AD2C2B-B2-F2B2C2(D46ADC3B-B2-F4B)D46AD2C2B-B2-F4BD46AD2C2B-B2-4BCD46ADC3B-B2-4BCD46AD4B-B2-2BE2CD46AD4B-B2-F2B2C2(D46A5B-B2-F3BC)D46A5B-B2-4BCD46A5B-B2-5BD46A5B-B2-3B2CD46A5B-B2-F2B2C13D34BD4B-B2-FBE8C3BC42B-B2-2BE6C48B-B2-3B6E48B-B2-57B-B2-24B7F12B6F8B2(-B2-57B)-B2-2F51BF3B2(-B2-F56B)-B2-15BC7B3C31B-B2-4B3C3B9C4B8C8B7C4B5C2B-B2-4BC48D2C2B-B2-4BCD46AD2C2B-B2-3B2(2CD46ADC3B-B2-2BE)2CD46AD2C2B-B2-B2E2(2CD46AD2C2B-B2-2BE)2CD46AD2C2B-B2-B2E2CD46ADC3B-B2-FBE2CD46ADC3B-B2-F2E2CD46AD2C2B-B2-FBE3(2CD46AD2C2B-B2-B2E)2CD46ADC3B-B2-B2E2CD46ADC3B-B2-3B2(2CD46AD2C2B-B2-2BE)3(2CD46ADC3B-B2-FBE)2CD46ADC3B-B2-B2E2CD46AD4B2(-B2-2BE2CD46ADC3B)-B2-2BE2CD46AD2C2B-B2-2BE2(2CD46ADC3B-B2-B2E)2CD46ADC3B-B2-2BE2CD46AD2C2B-B2-B2E2CD46ADC3B-B2-2BE2CD46AD2C2B-B2-FBE2CD46AD2CEB2(-B2-FBE2CD46AD2C2B)-B2-F4BD46AD2C2B2(-B2-F4BD46AD2CEB)-B2-4BCD46ADC3B-B2-3B2CD46ADC3B-B2-2BE2CD46ADC3B-B2-F2B2C2(D46AD4B-B2-F3BC)D46AD4B-B2-6B46AD4B-B2-5BD46AD4B-B2-F2B2CD46A5B-B2-F2B2C13D34BD4B-B2-FBE7C47B-B2-3B6C48B-B2-3B4E50B-B2-57B-B2-25B4F14B6F8B2(-B2-57B)-B2-2F13BF36B2F3B2(-B2-F56B)-B2-F21B3C32B-B2-4B25C11B4C7B3C3B-B2-4BC31DB16D2(2C2B-B2-3B2CD46AD)C3B4(-B2-2BE2CD46AD2C2B)2(-B2-2BE2CD46ADC3B)3(-B2-FBE2CD46ADC3B)-B2-2BE2CD46AD2C2B-B2-B2E2CD46AD2C2B-B2-2BE4(2CD46ADC3B-B2-3B)2CD46ADC3B-B2-2B2(E2CD46ADC3B-B2-FB)4(E2CD46ADC3B-B2-2B)E2CD46AD2C2B-B2-2BE2CD46ADC3B-B2-B2E2(2CD46ADC3B-B2-2BE)2CD46ADC3B-B2-3B2CD46ADC3B-B2-2BE2CD46ADC3B2(-B2-FBE2CD46AD2C2B)-B2-F2B2CD46AD2C2B-B2-F4BD46AD2CEB2(-B2-F5B46AD2C2B)-B2-6B46AD2C2B2(-B2-5BD46ADC3B)-B2-F3BCD46ADC3B2(-B2-F4BD46AD4B)2(-B2-5BD46AD4B)-B2-F2B2CD46AD4B-B2-F2B2C8D2B3D34BD4B-B2-F2B9C45B-B2-F2B6C48B-B2-4B3E50B-B2-57B-B2-9B3F32B4F9B2(-B2-57B)-B2-F13B4F33B3F3B2(-B2-F56B)-B2-F7B2C5BC2B6C33B-B2-4B22C12BC2B4C7B2C3B-B2-4BC24D6B11D2B5D3(C3B-B2-3B2CD46AD)6(2C2B-B2-2BE2CD46AD)2C2B2(-B2-F2B2CD46ADC3B)2(-B2-2BE2CD46ADC3B)-B2-3B2CD46ADC3B2(-B2-3B2CD46AD4B)3(-B2-3B2CD46ADC3B)6(-B2-2BE2CD46ADC3B)3(-B2-2BE2CD46AD4B)-B2-2BE2(2CD46ADC3B-B2-B2E)2CD46AD2C2B-B2-B2E2CD46AD2C2B-B2-FBE2CD46AD2CEB-B2-F2B2CD46AD2CEB-B2-F4BD3(46AD2C2B-B2-F5B)46ADC3B-B2-6B46ADC3B-B2-5BD46ADC3B-B2-F4BD2(46AD4B-B2-F5B)46AD4B-B2-5BD46AD4B-B2-4BCD46AD4B-B2-F2B2CD46AD4B-B2-F3BC9D38BD4B-B2-F2B10C44B-B2-F2B7C47B-B2-2B5E50B-B2-5BE51B-B2-8B5F32B2F10B2(-B2-57B)-B2-F13B6F11BF19B4F2B2(-B2-F56B)-B2-F7B3CB4C2B3CBC34B-B2-4B21C27BC4B-B2-4BC23D7B7D7B4D4B-B2-4BCD46ADC3B-B2-3B2CD46ADC3B3(-B2-2BE2CD46AD2C2B)-B2-3B2(2CD46AD2C2B-B2-2BE)2(2CD46AD2C2B-B2-3B)5(2CD46ADC3B-B2-3B)2C2(D46AD4B-B2-4BC)2(D46ADC3B-B2-4BC)2(D46ADC3B-B2-3B2C)5(D46ADC3B-B2-2BE2C)D46AD4B-B2-2BE2CD46ADBC2B-B2-2BE2CD46ADBC2(EB-B2-B2E2CD46AD2C)2(2B-B2-B2E2CD46AD2C)2B-B2-F2E2CD46AD2C2B-B2-FBE2CD46AD2C2B-B2-F5B46ADC3B2(-B2-F5B46AD2C2B)-B2-F5B46ADC3B-B2-6B46ADC3B-B2-5BD46ADC3B3(-B2-F4BD46AD4B)-B2-5BD46AD4B-B2-4B2(CD46AD4B-B2-F3B)C8D39BD4B-B2-F2B9C45B-B2-F2B6C48B-B2-3B4E50B-B2-57B-B2-7B7F43B2(-B2-57B)-B2-F13B8F7B4F16B6F2B2(-B2-F56B)-B2-F7B5C5BC3B2C33B-B2-5B20C32B-B2-4BC23D6B5D11B3DC3B-B2-4BC3(D46ADC3B-B2-3B2C)2(D46AD2C2B-B2-2BE2C)D46ADC3B2(-B2-2BE2CD46AD2C2B)2(-B2-3B2CD46AD2C2B)3(-B2-3B2CD46ADC3B)-B2-3B2CD46AD4B-B2-4BCD46AD4B2(-B2-3B2CD46ADC3B-B2-4BCD46ADC3B)3(-B2-3B2CD46ADC3B)-B2-2BE3(2CD46ADC3B-B2-B2E)2CD46ADBC2B-B2-B2E2CD46AD2C2B-B2-2BE2CD46AD2C2E-B2-2BE3(2CD46AD2CEB-B2-B2E)2CD46AD2CEB-B2-2BE2CD46AD2CEB-B2-F2E2CD46AD2C2B-B2-FBE2CD46AD2C2B-B2-F4BD46AD2C2B-B2-F5B46ADC3B-B2-F4B2(D46ADC3B-B2-5B)D46ADC3B-B2-F4BD46ADC3B2(-B2-F5B46AD4B)-B2-5BD46AD4B-B2-F3BC2(D46AD4B-B2-F2B2C)8D44B-B2-FBE9C45B-B2-FBE8C46B-B2-F3B3E50B-B2-57B-B2-7B8F42B2(-B2-57B)-B2-2F13B8F4B7F6B4F4B7F2B2(-B2-F56B)-B2-F7B5C3B3C4BC33B-B2-F4B20C28BC3B-B2-4BC21D9BD14B3D4B-B2-4BCD46AD4B2(-B2-3B2CD46ADC3B)-B2-3B4(2CD46AD2C2B-B2-2BE)3(2CD46AD2C2B-B2-3B)2CD46ADC3B-B2-3B2CD46ADC3B-B2-4BCD46AD4B-B2-3B2CD46ADC3B-B2-F2B2(2CD46AD4B-B2-3B)3(2CD46ADC3B-B2-3B)2(2CD46ADC3B-B2-2BE)4(2CD46ADC3B-B2-B2E)2CD46AD2C2B5(-B2-B2E2CD46AD2CEB)-B2-B2E2CD46AD2C2E-B2-B2E2CD46AD2CEB-B2-FBE2CD46AD2CEB-B2-F2B2CD46AD2C2B-B2-FBE2CD46ADC3B-B2-F2B2CD46ADC3B-B2-F3BC3(D46ADC3B-B2-5B)D46AD4B-B2-F4BD46AD4B-B2-F5B46A5B-B2-F4BD46A5B-B2-F3BCD46AD4B-B2-F2B2CD46A5B-B2-F3BC7D2(45B-B2-F2B9C)45B-B2-F3B3E50B-B2-57B-B2-6B14F37B2(-B2-57B)-B2-2F13B19F6B16FB2(-B2-F56B)-B2-F8B2CBC4BC5BC33B-B2-F3BC2B18C32B-B2-4BC21D4BD3BD16B2D2(4B-B2-4BCD46AD)2(C3B-B2-3B2CD46AD)C3B3(-B2-2BE2CD46AD2C2B)3(-B2-3B2CD46AD2C2B)-B2-2BE2(2CD46ADC3B-B2-3B)2CD46AD4B-B2-F2B2CD46AD4B-B2-FBE2CD46ADC3B2(-B2-3B2CD46AD4B)3(-B2-3B2CD46ADC3B)-B2-2BE2CD46AD2C2B2(-B2-2BE2CD46ADC3B)-B2-B2E2(2CD46ADC3B-B2-2BE)2CD46AD2CEB-B2-B2(2E2CD46AD2C2B-B2-G)2E2CD46AD2C2B-B2-B2E2CD46AD2C2E2(-B2-B2E2CD46AD2CEB)-B2-2BE2CD46AD2CEB2(-B2-FBE2CD46AD2C2B)-B2-FBE2CD46AD4B-B2-FBE2CD46ADC3B-B2-F2B2CD46AD4B-B2-2BEBCD46ADC3B-B2-3BCBD46ADC3B2(-B2-5BD46AD4B)-B2-F4B3(D46A5B-B2-F3BC)D46A5B-B2-F2B2C8D44B-B2-F2B9C45B-B2-F2B8C46B-B2-F3B3E50B-B2-57B-B2-4B17F36B2(-B2-57B)-B2-3F12B20F5B16FB2(-B2-F56B)-B2-F10B3C3BC5BC33B-B2-8B17C32B-B2-5B21D2B3D20B2D2(4B-B2-4BCD46AD)4B2(-B2-3B2CD46ADC3B)2(-B2-2BE2CD46AD2C2B)-B2-2BE2CD46AD2CEB2(-B2-3B2CD46AD2C2B)-B2-4BCD46ADC3B3(-B2-3B2CD46AD4B)-B2-F2B2CD46AD4B-B2-FBE2CD46ADC3B-B2-2BE2(2CD46ADC3B-B2-3B)2CD46AD4B2(-B2-2BE2CD46ADC3B)2(-B2-2BE2CD46AD2C2B)-B2-2BE2CD46AD4B-B2-B2E2CD46ADC3B-B2-G2E2CD46ADC3B-B2-B2E2CD46AD2C2B-B2-G2E2CD46AD2CEB2(-B2-G2E2CD46AD2C2B)-B2-2BE2(2CD46AD2CEB-B2-F2E)2CD46AD2CEB-B2-FBE2CD46AD2CEB-B2-B2E2CD46AD2C2B-B2-B2E2CD46ADC3B-B2-FBE2CD46AD4B-B2-F2B2CD46AD4B-B2-F3BCD46ADC3B-B2-4BC2(D46ADC3B-B2-5B)D46AD4B-B2-5BD2(46AD4B-B2-F5B)2(46A5B-B2-F3BCD)46A5B-B2-F2B2C7D45B-B2-F2B8C46B-B2-F2B5C49B-B2-F2B5E49B-B2-57B-B2-2B19F36B2(-B2-57B)-B2-3F13B20F4B16FB2(-B2-F56B)-B2-F10B4CB2C3B2C34B-B2-9B16C32B-B2-6B28D6BD10BD5B-B2-6B46A5B-B2-5BD46AD4B-B2-4BCD46ADC3B-B2-3B2(2CD46ADC3B-B2-2BE)2CD46AD2C2B-B2-2BE3(2CD46AD2C2B-B2-3B)3(2CD46ADC3B-B2-2BE)2(2CD46AD4B-B2-FBE)2CD46ADC3B-B2-FBE2CD46AD4B-B2-2BE2(2CD46ADC3B-B2-B2E)2(2CD46AD4B-B2-3B)2CD46ADC3B-B2-3B2CD46ADC3B2(-B2-B2E2CD46AD4B)-B2-B2E2CD46ADC3B2(-B2-B2E2CD46AD2C2B)-B2-G2E2CD46AD2C2B-B2-B2E2CD46ADC3B-B2-B2E3(2CD46AD2CEB-B2-FBE)2CD46AD2CEB-B2-2BE2(2CD46AD4B-B2-B2E)2CD46AD4B-B2-2BE2CD46AD4B-B2-FBE2CD46AD4B2(-B2-4BCD46ADC3B)-B2-5BD46AD4B-B2-6B46A5B-B2-F5B46A5B-B2-F4B3(D46A5B-B2-F2B2C)7D45B-B2-F2B8C46B-B2-F2B4C2BC47B-B2-F3B3E50B-B2-F56B-B2-20F37B2(-B2-57B)-B2-3F5B4F5B19F4B17F2(-B2-F56B)-B2-F12B4C4BC35B-B2-8BCB15C32B-B2-6B19DB4D10BD16B2(-B2-5BD46A5B)-B2-4BCD46AD4B-B2-3B2CD46AD4B-B2-2BE2(2CD46ADC3B-B2-3B)2CD46AD2C2B-B2-3B2CD46ADC3B-B2-4BC3(D46AD2C2B-B2-3B2C)D46ADC3B-B2-3B3(2CD46AD4B-B2-FBE)2CD46AD4B-B2-2BE2CD46ADC3B2(-B2-2BE2CD46AD4B)2(-B2-3B2CD46AD4B)2(-B2-2BE2CD46AD4B)-B2-B2E2CD46AD4B-B2-B2E2CD46A5B-B2-B2E2CD46AB2C2B-B2-B2E2CD46ADC3B2(-B2-B2E2CD46AD2C2B)-B2-2B3(E2CD46AD2CEB-B2-FB)E2CD46AD2C2B2(-B2-B2E2CD46ADC3B)-B2-B2E2CD46AD4B-B2-B2E2CD46A5B-B2-2BE2CD46A5B2(-B2-4BCD46AD4B)-B2-4BCD46A5B-B2-5B2(D46A5B-B2-F4B)3(D46A5B-B2-F2B2C)4D48B2(-B2-F2B3C51B)-B2-F4BE51B-B2-F56B-B2-18F39B2(-B2-57B)-B2-2F5B5F6B18F4B17F2(-B2-F56B)-B2-F13B2C4BC36B-B2-7B2C2B15C31B-B2-5B23D12BD16B-B2-5B2(D46A5B-B2-4BC)2(D46AD4B-B2-3B2C)D46ADC3B-B2-3B2CD46AD2C2B-B2-3B2C2(D46ADC3B-B2-4BC)D46ADC3B-B2-3B2CD46AD2C2B-B2-3B2CD46AD4B-B2-3B2CD46ADC3B-B2-4BCD46ADC3B-B2-3B2(2CD46AD4B-B2-F2B)2CD46AD4B-B2-FBE2CD46ADC3B-B2-2BE2CD46AD4B-B2-2BE2CD46A5B-B2-2BE2(2CD46AD4B-B2-3B)2CD46A5B-B2-2BE2(2CD46AD4B-B2-B2E)2CD46A5B2(-B2-B2E2CD46AD2C2B)2(-B2-B2E2CD46AD4B)-B2-B2E2CD46ADC3B-B2-FBE2CD46AD2C2B-B2-F2E2CD46ADC3B-B2-2BE2CD46AD2C2B2(-B2-2BE2CD46ADC3B)2(-B2-B2E2CD46A5B)-B2-2BE2C3(D46A5B-B2-4BC)D46A5B-B2-3B2CD46A5B-B2-4BCD46A5B-B2-F3BCD46A5B-B2-F4BD46A5B-B2-F3BCD46A5B-B2-F2B2CD51B-B2-F2B2C52B-B2-3BC53B-B2-57B-B2-F56B-B2-17F25B3F12B2(-B2-57B)-B2-F6B6F6B17F4B17F2(-B2-F56B)-B2-F12BC43B-B2-5B3CB18C30B-B2-5B24D6B2D2B2D16B2(-B2-4BCD46A5B)2(-B2-4BCD46AD4B)-B2-3B2CD46ADC3B-B2-3B2CD46AD2C2B-B2-4BCD46ABC3B2(-B2-3B2CD46AD2C2B)-B2-3B2CD46ADC3B3(-B2-4BCD46AD4B)-B2-3B2CD46AD4B-B2-F2B2(2CD46AD4B-B2-FBE)2CD46ADC3B-B2-F2E2CD46AD4B-B2-2BE2CD46AD4B2(-B2-B2E2CD46A5B)3(-B2-B2E2CD46AD4B)-B2-B2E2CD46ABC3B-B2-B2E2CD46AD2C2B-B2-B2E2CD46ADC3B2(-B2-B2E2CD46AD4B)-B2-2BE2CD46AD4B2(-B2-FBE2CD46ADC3B)-B2-3B2CD46AD4B-B2-B2E2CD46ADC3B-B2-B2E2CD46AD4B-B2-B2E2CD46ABC3B2(-B2-B2E2CD46A5B)-B2-2BE2C4(D46A5B-B2-4BC)4(D46A5B-B2-F3BC)D51B-B2-F2B2C52B2(-B2-57B)-B2-F56B-B2-15F27B4F11B2(-B2-57B)-B2-7B7F7BF6B8F4B16FB2(-B2-F56B)-B2-15BC3B5C33B-B2-4BCB20C9B3C19B-B2-5B22D7B5D2BD8BD6B2(-B2-4BCD46A5B)2(-B2-4BCD46AD4B)-B2-3B2CD46AD4B-B2-4BCD46ADC3B-B2-3B2CD46AB2C2B-B2-4BCD46A5B-B2-3B2CD46ADC3B5(-B2-4BCD46AD4B)-B2-3B2CD46ADC3B-B2-FBE2CD46A5B-B2-FBE2CD46AD4B-B2-F2(2E2CD46AD4B-B2-B)2(2E2CD46A5B-B2-B)2E2CD46AD4B-B2-G2E2CD46AD4B2(-B2-B2E2CD46A5B)-B2-B2E2CD46AD4B-B2-G2(2E2CD46AD4B-B2-B)2E2CD46A5B-B2-B2E2CD46A5B-B2-F2E2CD46AD4B-B2-2BE2CD46ADC3B2(-B2-2BE2CD46AD4B)-B2-B2E2CD46ADC3B-B2-G2E2CD46A5B-B2-B2E2CD46ADC3B2(-B2-B2E2CD46A5B)-B2-3B2C2(D46A5B-B2-4BC)D46A5B-B2-5B2(D46A5B-B2-F3BC)D46A5B-B2-F2BCBD46A5B-B2-F2B2CDB2D48B-B2-3B2C52B2(-B2-57B)-B2-F56B-B2-14F27B5F11B2(-B2-57B)-B2-8B6F16B5F5B16FB-B2-57B-B2-F56B-B2-19B5C33B-B2-6BC3B15C9B2C21B-B2-5B22D5B6D3BD15B2(-B2-4BCD46A5B)3(-B2-4BCD46AD4B)-B2-3B2C7(D46A5B-B2-4BC)2(D46AD4B-B2-4BC)2(D46A5B-B2-F2B2C)D46A5B-B2-FBE2CD46A5B-B2-F7(2E2CD46A5B-B2-B)4(2E2CD46A5B-B2-G)2E2CD46AD4B-B2-G3(2E2CD46AD4B-B2-B)3(2E2CD46AD4B-B2-G)2E2CD46AD4B-B2-2BE2CD46ADC3B3(-B2-2BE2CD46A5B)-B2-3B2C2(D46A5B-B2-4BC)D46A5B-B2-F3BC2(D46A5B-B2-F2B2C)4D6BD41B4(-B2-57B)-B2-13F28B5F11B2(-B2-57B)-B2-9B6F16B3F5B16F2B-B2-57B-B2-21B2E34B-B2-12BC5B6C33B-B2-8B17C8BCB2C20B-B2-5B22D3B9D2(B3D)10B-B2-5B3(D46A5B-B2-4BC)2(D46AD4B-B2-3B2C)D46AD4B2(-B2-4BCD46A5B)2(-B2-3B2CD46A5B)2(-B2-4BCD46A5B)-B2-5B2(D46A5B-B2-4BC)D46A5B-B2-F3BCD46A5B-B2-F2B2CD46AD4B2(-B2-FBE2CD46A5B)9(-B2-B2E2CD46A5B)2(-B2-G2E2CD46A5B)2(-B2-G2E2CD46AD4B)3(-B2-B2E2CD46AD4B)-B2-G2(2E2CD46AD4B-B2-B)2E2CD46ADC3B-B2-B2E3(2CD46A5B-B2-2BE)2C2(D46A5B-B2-4BC)D46A5B-B2-5BD46A5B-B2-F3BCD46A5B-B2-3B2C6D3B3D40B4(-B2-57B)-B2-12F30B4F11B2(-B2-57B)-B2-10B6F16BF6B8F4B3F3B-B2-19B2E36B-B2-18B5E34B-B2-8B16C33B-B2-8B18C5BC4BC2B3C15B-B2-5B23DB17D11B7(-B2-4BCD46A5B)2(-B2-3B2CD46A5B-B2-4BCD46A5B)-B2-4BC2(D46A5B-B2-5B)D46A5B-B2-4B3(CD46A5B-B2-F3B)CD46A5B-B2-FB4(E2CD46A5B-B2-2B)E5(2CD46A5B-B2-B2E)4(2CD46A5B-B2-G2E)2CD46AD4B-B2-G3(2E2CD46AD4B-B2-B)3(2E2CD46A5B-B2-B)2E2(2CD46A5B-B2-2BE)2(2CD46A5B-B2-3B)2C2(D46A5B-B2-4BC)2(D46A5B-B2-5B)DB4D3B2D41B4(-B2-57B)-B2-B10F46B2(-B2-57B)-B2-11B6F21B8F11B-B2-19B3E35B-B2-18B6E33B-B2-10B5CB8C16BC3BC12B-B2-4B2C2B18C4B3C6B4CBC12B-B2-4BC32D2B6DBD10B4(-B2-5BD46A5B)3(-B2-4BCD46A5B)3(-B2-3B2CD46A5B)2(-B2-4BCD46A5B)4(-B2-5BD46A5B)-B2-F3BC2(D46A5B-B2-F2B2C)D46A5B-B2-FB2(E2CD46A5B-B2-2B)E2CD46A5B-B2-B2E2CD46A5B-B2-2BE2(2CD46A5B-B2-B2E)2CD46AD4B-B2-G2E2CD46AD4B-B2-B2E2CD46AD4B4(-B2-G2E2CD46A5B)2(-B2-B2E2CD46AD4B)2(-B2-B2E2CD46A5B)-B2-G2E2CD46A5B-B2-B2E2(2CD46A5B-B2-2BE)2CD46A5B-B2-3B2C4(D46A5B-B2-4BC)2(D46A5B-B2-5B)3D6BD42B4(-B2-57B)-B2-3B4F50B2(-B2-57B)-B2-12B6F20B7F12B-B2-19B2E36B-B2-18B5E34B-B2-13B2C2B8C32B-B2-4B3C2B25C6B4C13B-B2-4BC31D2B8D11B-B2-5BD46A5B-B2-F4B2(D46A5B-B2-5B)2(D46A5B-B2-4BC)D46A5B-B2-3B2CD46A5B-B2-4BCD46A5B-B2-3B2CD46A5B-B2-F2B2CD46A5B-B2-F3B3(CD46A5B-B2-4B)CD46A5B-B2-5BD46A5B-B2-4B2(CD46A5B-B2-F3B)C2(D46A5B-B2-F2B2C)D46A5B-B2-2BE5(2CD46A5B-B2-B2E)2CD46A5B-B2-G2E2CD46AD4B3(-B2-B2E2CD46A5B)2(-B2-G2E2CD46A5B)-B2-B2E2CD46A5B-B2-B2E2CD46AD4B-B2-B2E2CD46A5B-B2-G2(2E2CD46A5B-B2-B)2E2CD46A5B-B2-2BE2CD46A5B-B2-3B2C4(D46A5B-B2-4BC)3(D46A5B-B2-5B)3D11BD37B7(-B2-57B)-B2-12B7F18B7F13B-B2-57B-B2-18B4EBE33B-B2-11B2CBC2B9C3BC27B-B2-4B29C7B5C12B-B2-4BC31D2B7D12B-B2-5B2(D46A5B-B2-F4B)2(2(D46A5B-B2-5B)D46A5B-B2-4BC)2(D46A5B-B2-F2B2C)3(D46A5B-B2-4BC)D46A5B-B2-5B2(D46A5B-B2-4BC)D46A5B-B2-F3BC2(D46A5B-B2-F2B2C)D46A5B-B2-FBE2CD46A5B-B2-B2E2CD46A5B-B2-2BE3(2CD46A5B-B2-B2E)2(2CD46A5B-B2-G2E2CD46A5B-B2-B2E)2CD46AD4B2(-B2-G2E2CD46A5B)-B2-B2E2CD46A5B2(-B2-B2E2CD46AD4B)-B2-G2E2CD46AD4B2(-B2-B2E2CD46A5B)-B2-2BE2CD46A5B-B2-4BCD46A5B-B2-F3B2(CD46A5B-B2-4B)CD46A5B-B2-5BD3(46A5B-B2-6B)2D6BD4BD37B7(-B2-57B)-B2-12B7F18B6F14B-B2-57B-B2-17B4E36B-B2-14B11C2B3C4BC22B-B2-4BC3B24C7B4C14B-B2-5B28DB12D11B-B2-5B2(D46A5B-B2-F4B)4(D46A5B-B2-5B)D46A5B-B2-4BC2(D46A5B-B2-3B2C)D46A5B-B2-F3BC2(D46A5B-B2-3B2C)4(D46A5B-B2-4BC)3(D46A5B-B2-F2B2C)D46A5B-B2-FB2(E2CD46A5B-B2-2B)E7(2CD46A5B-B2-B2E)2(2CD46AD4B-B2-G2E)2CD46A5B2(-B2-G2E2CD46AD4B)3(-B2-B2E2CD46A5B)-B2-B2E2CD46AD4B-B2-2BE2CD46A5B-B2-5BD46A5B-B2-F3BCD46A5B-B2-F4BD46A5B-B2-5BD3(46A5B-B2-6B)46A5B-B2-10BD46B7(-B2-57B)-B2-12B7F17B7F14B-B2-57B-B2-17B4E8BE27B-B2-15B10CB4C27B-B2-4B30C5B2C16B-B2-4BC30D3B8D11B-B2-4BCD46A5B-B2-F3BCD46A5B-B2-5BD46A5B-B2-4BC3(D46A5B-B2-5B)D46A5B-B2-4BC2(D46A5B-B2-3B2C)2(2(D46A5B-B2-4BC)D46A5B-B2-3B2C)D46A5B-B2-4BCD46A5B-B2-3B2(2CD46A5B-B2-F2B)2CD46A5B-B2-FB2(E2CD46A5B-B2-2B)E5(2CD46A5B-B2-B2E)2(2CD46A5B-B2-G2E)2(2CD46AD4B-B2-B2E)2CD46A5B-B2-B2E2CD46AD4B-B2-G2(2E2CD46AD4B-B2-B)2E2(2CD46A5B-B2-2BE)2CD46A5B-B2-3B2CD46A5B-B2-4BCD46A5B-B2-F3BCD46A5B-B2-F4BD4(46A5B-B2-6B)46A5B-B2-10BD46B4(-B2-57B)-B2-42B3F12B2(-B2-57B)-B2-3B2F7B7F17B6F15B-B2-57B-B2-16B2EB2E7BE28B-B2-5B2C2BC4B7CB2C4BC28B-B2-4B3CB23C2B2C4B2C16B-B2-4BC40D12B2(-B2-4BCD46A5B)-B2-5BD46A5B-B2-3BCB2(D46A5B-B2-5B)D46A5B-B2-4BC2(D46A5B-B2-3B2C)3(D46A5B-B2-4BC)2(D46A5B-B2-3B2C)2(D46A5B-B2-4BC)2(D46A5B-B2-3B2C)D46A5B-B2-F3BCD46A5B-B2-F2B2CD46A5B-B2-FBE4(2CD46A5B-B2-B2E)5(2CD46A5B-B2-G2E)2CD46AD4B2(-B2-G2E2CD46A5B)2(-B2-B2E2CD46A5B)3(-B2-2BE2CD46A5B)2(-B2-3B2CD46A5B)-B2-4BC2(D46A5B-B2-F4B)D46A5B-B2-F5B3(46A5B-B2-6B)46A5B5(-B2-57B)-B2-42B3F12B2(-B2-57B)-B2-B4F7B7F18B4F16B-B2-F56B-B2-20BE7BE4B2E22B-B2-3B4CB3C3B8C2B5C7BC20B-B2-3B28CB3CB5C16B-B2-3B2C38D4BD9B-B2-3B2C3(D46A5B-B2-4BC)2(D46A5B-B2-5B)2(D46A5B-B2-4BC4(D46A5B-B2-3B2C))2(D46A5B-B2-3B2C)D46A5B-B2-F2B2CD46A5B-B2-FBE2CD46A5B-B2-F4(2E2CD46A5B-B2-B)9(2E2CD46A5B-B2-G)2E2CD46A5B-B2-B2E2CD46A5B-B2-2BE2(2CD46A5B-B2-3B)2C2(D46A5B-B2-4BC)2(D46A5B-B2-F4B)D46A5B-B2-F5B3(46A5B-B2-6B)46A5B5(-B2-57B)-B2-42B2F13B2(-B2-57B)-B2-5F7B7F18B2F10B5F3B-B2-F56B-B2-F2B2E28B3E21B-B2-2BE8C4B7C2BC2B4C2B5C19B-B2-3B38C16B-B2-3B2C39D5BD7B-B2-3B2CD46A5B-B2-2BE2CD46A5B-B2-4BCD46A5B-B2-5B3(D46A5B-B2-4BC)D46A5B-B2-3B2CD46A5B-B2-4BC9(D46A5B-B2-3B2C)3(D46A5B-B2-FBE2C)3(D46A5B-B2-B2E2C)10(D46A5B-B2-G2E2C)D46A5B-B2-B2E2(2CD46A5B-B2-2BE)B3(CD46A5B-B2-4B)CD46A5B-B2-F4BD2(46A5B-B2-F5B)46A5B-B2-6B46A5B-B2-5BD46A5B-B2-6B46A5B8(-B2-57B)-B2-5F7B6F29B8F2B-B2-F56B-B2-F2(2B2E)9B3E14BE21B-B2-2BE8C3B11C2B6CB4C19B-B2-3B39C15B-B2-3B2C39D5B2D6B5(-B2-3B2CD46A5B)-B2-4BC2(D46A5B-B2-3B2C)2(D46A5B-B2-4BC)D46A5B-B2-3B2CD46A5B-B2-2BE6(2CD46A5B-B2-3B)2CD46A5B-B2-F2B2CD46A5B-B2-FBE2CD46A5B-B2-2BE2(2CD46A5B-B2-B2E)8(2CD46A5B-B2-G2E)2(2CD46A5B-B2-B2E)2CD46A5B-B2-G2E2CD46A5B-B2-B2E3(2CD46A5B-B2-2BE)BCD46A5B-B2-4BCD46A5B-B2-5BD46A5B-B2-F3BC2(D46A5B-B2-F4B)D46A5B-B2-5BD2(46A5B-B2-6B)46A5B8(-B2-57B)-B2-4F42B9F2B-B2-F18BE37B-B2-FB7E6B8E34B-B2-2BE8CB17CB7C20B-B2-3B39C15B-B2-3B2C40D2B2DB2D9(5B-B2-3B2CD46A)2(5B-B2-4BC2(D46A5B-B2-3B2C)D46A)4(5B-B2-3B2CD46A)5B-B2-2BE4(2CD46A5B-B2-B2E)11(2CD46A5B-B2-G2E)2CD46A5B-B2-B2E2CD46A5B-B2-2BE2C2(D46A5B-B2-4BC)4(D46A5B-B2-F4B)D46A5B-B2-5BD2(46A5B-B2-6B)46A5B8(-B2-57B)-B2-4F41B11FB-B2-F18B5E33B-B2-2B7E4BEB10E32B-B2-3B25C2B7C20B-B2-3B39CBC13B-B2-3B2C40D2B2D8B-B2-3B2(2CD46A5B-B2-2BE3(2CD46A5B-B2-3B))2C4(D46A5B-B2-4BC)5(D46A5B-B2-3B2C)4(D46A5B-B2-2BE2C)2(D46A5B-B2-B2E2C)D46A5B-B2-G2E2CD46A5B-B2-B8(2E2CD46A5B-B2-G)3(2E2CD46A5B-B2-B)2E2CD46A5B-B2-3B2CD46A5B-B2-4B2(CD46A5B-B2-F3B)CD46A5B-B2-F4B2(D46A5B-B2-F3BC)D2(46A5B-B2-6B)46A5B8(-B2-57B)-B2-3F18B2F22B11FB-B2-F17B2EB4E32B-B2-2BEB5E2B15E31B-B2-3B30C24B-B2-3B39C15B-B2-3B2C39D4BD8B-B2-3B2CD46A5B-B2-FBE2CD46A5B-B2-2BE2CD46A5B-B2-3B3(2CD46A5B-B2-2BE)2(2CD46A5B-B2-3B)2C4(D46A5B-B2-4BC)2(D46A5B-B2-3B2C)7(D46A5B-B2-2BE2C)3(D46A5B-B2-B2E2C)9(D46A5B-B2-G2E2C)2(D46A5B-B2-B2E2C)D46A5B-B2-2BE2CD46A5B-B2-4BCD46A5B-B2-F2B2C3(D46A5B-B2-F3BC)2(D46A5B-B2-F4B)D2(46A5B-B2-6B)46A5B8(-B2-57B)-B2-F16B2G2BF2GF19B13F-B2-13B12E32B-B2-2B7EB18E29B-B2-2BE30C24B-B2-2BE38C16B-B2-2BE2C40D12B3(-B2-FBE2CD46A5B)-B2-3B3(2CD46A5B-B2-2BE)3(2CD46A5B-B2-3B)2CD46A5B-B2-F2B2CD46A5B-B2-F3BC3(D46A5B-B2-3B2C)7(D46A5B-B2-2BE2C)3(D46A5B-B2-B2E2C)7(D46A5B-B2-G2E2C)3(D46A5B-B2-B2E2C)D46A5B-B2-2BE2(2CD46A5B-B2-3B)2(2CD46A5B-B2-F2B)2C2(D46A5B-B2-F3BC)D46A5B-B2-F4BD3(46A5B-B2-F5B)46A5B-B2-F56B4(-B2-57B)-B2-4B5F8B6F34B2(-B2-57B)-B2-17BG3B4G19B6F2B5F-B2-2B2EBE7B14E30B-B2-B27EB3E25B-B2-B2E30C24B-B2-B2E31CB4C18B-B2-B2E2C40D6B2D4B3(-B2-FBE2CD46A5B)4(-B2-2BE2CD46A5B)3(-B2-3B2CD46A5B)2(-B2-F2B2CD46A5B)4(-B2-3B2CD46A5B)7(-B2-2BE2CD46A5B)2(-B2-B2E2CD46A5B)2(-B2-G2E2CD46A5B)-B2-B4(2E2CD46A5B-B2-G)4(2E2CD46A5B-B2-B)2E2CD46A5B-B2-3B2(2CD46A5B-B2-F2B)2C4(D46A5B-B2-F3BC)D3(46A5B-B2-F5B)46A5B-B2-F11BD44B-B2-F56B3(-B2-57B)-B2-12F2B11F32B2(-B2-57B)-B2-2B2G7BG8B6G17B6F3B5F-B2-B5E3B19E29B-B2-B30E26B-B2-G2E30C24B-B2-G2E31C2BC14BC5B-B2-G2E2C39D5B4D4B-B2-F2E2(2CD46A5B-B2-FBE)6(2CD46A5B-B2-2BE)2CD46A5B-B2-3B2(2CD46A5B-B2-F2B)4(2CD46A5B-B2-3B)2(2CD46A5B-B2-2BE)2CD46A5B-B2-B2E3(2CD46A5B-B2-2BE)2(2CD46A5B-B2-B2E)3(2CD46A5B-B2-G2E)2CD46A5B-B2-B4(2E2CD46A5B-B2-G)2E2CD46A5B-B2-B2E2CD46A5B-B2-G2(2E2CD46A5B-B2-B)2E2CD46A5B-B2-2BE2(2CD46A5B-B2-F2B)2C4(D46A5B-B2-F3BC)D46A5B-B2-F4BD2(46A5B-B2-F5B)46A5B-B2-F11BD44B2(-B2-F56B)-B2-57B-B2-F56B-B2-26F31B2(-B2-57B)-B2-B4G7B3F4BGB7G15B6F3B5F-B2-G6EB20E29B-B2-B31E25B-B2-G2E29C25B-B2-G2E31C18BC4B-B2-G2E2C39DBD2B5D4B-B2-G2E2CD46AD4B-B2-FBE2CD46AD4B2(-B2-2BE2CD46A5B)-B2-3B3(2CD46A5B-B2-2BE)2(2CD46AD4B-B2-3B)3(2CD46A5B-B2-3B)2C2(D46A5B-B2-4BC)D46A5B-B2-3B2CD46A5B-B2-2BE3(2CD46A5B-B2-B2E)2(2CD46A5B-B2-2BE)10(2CD46A5B-B2-G2E)2CD46A5B-B2-B2E2CD46A5B-B2-G2E2CD46A5B-B2-B2E2(2CD46A5B-B2-2BE)2CD46A5B-B2-F3BCD46A5B-B2-F2B2C4(D46A5B-B2-F3BC)D46A5B-B2-F4BD2(46A5B-B2-F5B)46A5B-B2-F11BD44B4(-B2-F56B)-B2-27F30B2(-B2-57B)-B2-B5G5BF4GB2G2B3F5G14B6F3B5F-B2-G6E4B17E29B-B2-G31E25B-B2-G2E29C25B-B2-G2E30C20BC3B-B2-G2E2C32DB3D2(2BD)B5DC3B-B2-G2E2CD46AD4B-B2-G2E2CD46ADC3B2(-B2-2BE2CD46AD4B)2(-B2-2BE2CD46A5B)-B2-B2E3(2CD46A5B-B2-2BE)3(2CD46A5B-B2-3B)2CD46A5B-B2-4BC2(D46A5B-B2-3B2C)6(D46A5B-B2-2BE2C)9(D46A5B-B2-G2E2C)D46A5B-B2-F3(2E2CD46A5B-B2-B)2E2(2CD46A5B-B2-2BE)2CD46A5B-B2-F2B2C5(D46A5B-B2-F3BC)2(D46A5B-B2-F4B)D46A5B-B2-F5B46A5B-B2-F9B2D45B4(-B2-F56B)-B2-28F29B2(-B2-57B)-B2-7G4BF10GF5G14B7F3B5F-B2-G7E3B17E29B-B2-G30E26B-B2-G2E28C26B-B2-G2E30C19B2C3B-B2-G2E2C32D2BD3B2(D2B)4D2(C3B-B2-G2E2CD46AD)4B2(-B2-B2E2CD46ADC3B)3(-B2-B2E2CD46AD4B)-B2-B2E3(2CD46A5B-B2-2BE)5(2CD46A5B-B2-3B)5(2CD46A5B-B2-2BE)2(2CD46A5B-B2-B2(2E2CD46A5B-B2-G)2E)2CD46A5B-B2-B2E2CD46A5B-B2-G2(2E2CD46A5B-B2-B)2E2CD46A5B-B2-F2(2E2CD46A5B-B2-B)2E3(2CD46A5B-B2-2BE)2CD46A5B-B2-FBE2CD46A5B-B2-F3BC3(D46A5B-B2-F2B2C)3(D46A5B-B2-F3BC)D46A5B-B2-F5B46A5B-B2-F9B2D45B4(-B2-F56B)-B2-15F5B9F28B2(-B2-57B)-B2-6G4B2F10GF5G14B8F2B5F-B2-G7E4B16E29B-B2-G7EBEB18EBE26B-B2-G2E28C26B-B2-G2E29C20B2C3B-B2-G2E2C28D15B5D3(C3B-B2-G2E2CD46AD)3(C3B-B2-B2E2CD46AD)C3B-B2-G2E2CD46AD4B2(-B2-B2E2CD46A5B)-B2-3B2CD46A5B-B2-2BE5(2CD46A5B-B2-3B)5(2CD46A5B-B2-2BE)2(2CD46A5B-B2-B2E2CD46A5B-B2-G2E)2CD46A5B-B2-G5(2E2CD46A5B-B2-B)2E2CD46A5B-B2-F2E2CD46A5B-B2-B2E4(2CD46A5B-B2-2BE)2CD46A5B-B2-FBE2(2CD46A5B-B2-F2B)2CD46A5B-B2-FBE2CD46A5B-B2-F2B2C4(D46A5B-B2-F4B)D46A5B-B2-F9B3D44B4(-B2-F56B)-B2-15F6B10F26B2(-B2-57B)-B2-F5G4B3F9GF2GF17B14F-B2-G7E5B15E29B-B2-G28E28B-B2-G2E28C26B-B2-G2E29C25B-B2-G2E2C28D15B2DB2D2(4B-B2-G2E2CD46AD)4(C3B-B2-B2E2CD46AD)C3B-B2-G2E2CD46AD4B-B2-B2E2(2CD46A5B-B2-2BE4(2CD46A5B-B2-3B))3(2CD46A5B-B2-2BE)5(2CD46A5B-B2-B2E)2(2CD46A5B-B2-G2E)5(2CD46A5B-B2-B2E)4(2CD46A5B-B2-2BE)2(2CD46A5B-B2-F2B)2CD46A5B-B2-FBE2(2CD46A5B-B2-F2B)2CD46A5B-B2-F3BC2(D46A5B-B2-F4B)D46A5B-B2-F5B46A5B-B2-F4BD3B4D44B-B2-F3BC52B3(-B2-F56B)-B2-14F8B10F25B2(-B2-57B)-B2-F4GBG2B4FGF9GBG18B13F-B2-G9E3BEB14E28B-B2-G29E27B-B2-G2E29C25B-B2-G2E30C24B-B2-G2E2C29D5BD7B2D8B2(-B2-G2E2CD46AD4B)2(-B2-B2E2CD46ADC3B)-B2-G2E2CD46ADC3B2(-B2-B2E2CD46AD4B)-B2-2BE4(2CD46A5B-B2-3B)3(2CD46A5B-B2-2BE)4(2CD46A5B-B2-3B)2CD46A5B-B2-2BE6(2CD46A5B-B2-B2E)2(2CD46A5B-B2-G2E)7(2CD46A5B-B2-B2E)2(2CD46A5B-B2-2BE)3(2CD46A5B-B2-FBE)2CD46A5B-B2-2BE2CD46A5B-B2-3B2CD46A5B-B2-4BCD46A5B-B2-F4BD46A5B-B2-F3BC2(D46A5B-B2-F4B)4DB4D43B-B2-F3B5C48B-B2-F2B2C3BC48B2(-B2-F56B)-B2-13F9B10F25B2(-B2-57B)-B2-7G2B4FG2B11G18B12F-B2-G9E6B12E29B-B2-G11EB18E26B-B2-G2E28C26B-B2-G2E29C25B-B2-G2E2C27D5BD19B2(-B2-G2E2CD46AD4B)5(-B2-B2E2CD46AD4B)2(-B2-2BE5(2CD46A5B-B2-3B)2CD46A5B)2(-B2-2BE2CD46A5B)-B2-B2E2CD46A5B-B2-2BE2CD46A5B-B2-B3(2E2CD46A5B-B2-G)2(2E2CD46A5B-B2-B)2E2(2CD46A5B-B2-2BE)4(2CD46A5B-B2-B2E)2CD46A5B-B2-2BE2(2CD46A5B-B2-F2E)2CD46A5B-B2-FB2(E2CD46A5B-B2-2B)E2CD46A5B-B2-3B2C2(D46A5B-B2-4BC)3(D46A5B-B2-F3BC)9D43B-B2-F3B7C46B-B2-F2B6C48B2(-B2-F56B)-B2-2FB9F11B8F26B2(-B2-57B)-B2-F7G2B3F3B11G19B11F-B2-F8E5BEB13E28B-B2-G9E2B19E26B-B2-G2E29C25B-B2-G2E30C24B-B2-G2E2C28D2B3D19B-B2-G2E2CD46A5B-B2-G5(2E2CD46AD4B-B2-B)2E2CD46A5B-B2-2BE4(2CD46A5B-B2-3B)3(2CD46A5B-B2-2BE)3(2CD46A5B-B2-3B)2CD46A5B-B2-2BE2CD46A5B-B2-3B2(2CD46A5B-B2-2BE)7(2CD46A5B-B2-B2E)2(2CD46A5B-B2-2BE)2CD46A5B-B2-3B3(2CD46A5B-B2-B2E)2CD46A5B-B2-2BE2(2CD46A5B-B2-F2E)3(2CD46A5B-B2-B2E)2CD46A5B-B2-3B2C2(D46A5B-B2-4BC)3(D46A5B-B2-F3BC)11D41B-B2-F2B8CB2C43B-B2-F2B7C47B-B2-F3BEBE50B-B2-57B-B2-6B2F16B5F28B2(-B2-57B)-B2-FB6G8B9G23B8FB-B2-F9E5B13E29B-B2-B29E27B-B2-B2E29C25B-B2-G2E30C24B-B2-G2E2C28D24B2(-B2-G2E2CD46A5B)2(-B2-B2E2CD46A5B)-B2-2BE2CD46A5B-B2-B2E2(2CD46A5B-B2-2BE)2(2CD46A5B-B2-3B)3(2CD46A5B-B2-2BE)2(2CD46A5B-B2-B2E)2CD46A5B-B2-2BE2CD46A5B-B2-3B5(2CD46A5B-B2-2BE)2CD46A5B-B2-B2E2CD46A5B-B2-2BE4(2CD46A5B-B2-B2E)2(2CD46A5B-B2-2BE)2(2CD46A5B-B2-3B)3(2CD46A5B-B2-2BE)2CD46A5B-B2-B2(2E2CD46A5B-B2-F)2E2CD46A5B-B2-B2E4(2CD46A5B-B2-2BE)2CD46A5B-B2-3B2C3(D46A5B-B2-F3BC)12DBD38B-B2-F2B7C2B2C43B-B2-F2B7C47B-B2-6BEBE48B-B2-57B-B2-26BF30B2(-B2-57B)-B2-F2B3G7BG2B9G24B7FB-B2-F25E31B-B2-F28E28B-B2-B2E28C26B-B2-G2E30C24B-B2-B2E2C29D23B-B2-G3(2E2CD46A5B-B2-B)2E2(2CD46A5B-B2-2BE)2CD46A5B-B2-B2E2CD46A5B-B2-2BE2(2CD46A5B-B2-3B)4(2CD46A5B-B2-2BE)2(2CD46A5B-B2-B2E2(2CD46A5B-B2-2BE))4(2CD46A5B-B2-2BE)3(2CD46A5B-B2-B2E)9(2CD46A5B-B2-2BE)2CD46A5B-B2-F2E2(2CD46A5B-B2-2BE)2CD46A5B-B2-3B2CD46A5B-B2-2BE4(2CD46A5B-B2-3B)2(2CD46A5B-B2-F2B)2C13D39B-B2-F2B10CBC42B-B2-F2B7C47B-B2-4B3E50B4(-B2-57B)-B2-F9B14G26B5F2B-B2-F3EB20E32B-B2-F26E30B-B2-G2E26C28B-B2-G2E29C25B-B2-B2E2C28D24B7(-B2-B2E2CD46A5B)2(-B2-2BE2CD46A5B)2(-B2-3B2CD46A5B)3(-B2-2BE2CD46A5B)2(-B2-B2E2CD46A5B)2(-B2-2BE2CD46A5B)-B2-B2E16(2CD46A5B-B2-2BE)2(2CD46A5B-B2-B2E)3(2CD46A5B-B2-2BE)2CD46A5B-B2-4BC2(D46A5B-B2-3B2C)D46A5B-B2-2BE2CD46A5B-B2-3B2(2CD46A5B-B2-F2B)2C13D39B-B2-F2B10C44B-B2-F2B7C3BC43B-B2-4B3E50B4(-B2-57B)-B2-F8B14G29B2F3B-B2-FE6B15E34B-B2-F23E33B-B2-G2E25C29B-B2-2BE29C25B-B2-GBE2C28D24B4(-B2-B2E2CD46A5B)2(-B2-G2E2CD46A5B)3(-B2-B2E2CD46A5B)4(-B2-2BE2CD46A5B)-B2-B2E2(2CD46A5B-B2-2BE)3(2CD46A5B-B2-B2E)4(2CD46A5B-B2-2BE)2CD46A5B-B2-3B9(2CD46A5B-B2-2BE)5(2CD46A5B-B2-B2E)2CD46A5B-B2-2BE2CD46A5B-B2-3B2C2(D46A5B-B2-4BC)2(D46A5B-B2-3B2C)D46A5B-B2-2BE2(2CD46A5B-B2-F2B)2C9DBD41B-B2-F2B11C43B-B2-F2B9C45B-B2-F3B2E51B-B2-57B-B2-12B7F38B2(-B2-57B)-B2-F10B11G35B-B2-F5B2EB13E35B-B2-FB21E34B-B2-F2E21C2BC30B-B2-B2E26CBC26B-B2-B2E2C27D25B2(-B2-B2E2CD46A5B-B2-G2E2CD46A5B)2(-B2-G2E2CD46A5B)3(-B2-B2E2CD46A5B)4(-B2-2BE2CD46A5B)6(-B2-B2E2CD46A5B)4(-B2-2BE2CD46A5B)2(-B2-3B2CD46A5B)9(-B2-2BE2CD46A5B)-B2-B2E2(2CD46A5B-B2-2BE)2(2CD46A5B-B2-B2E)2CD46A5B-B2-2BE2CD46A5B-B2-F3B3(CD46A5B-B2-4B)CD46A5B-B2-3B2(2CD46A5B-B2-F2B)2C10D42B2(-B2-F2B11C43B)-B2-F3B2E51B-B2-F56B-B2-F8B12F36B2(-B2-57B)-B2-F6B3G2B4G4BG16B3F17B-B2-F5BEB14E35B-B2-FB20E35B-B2-FBE20C3BC30B-B2-F2E26CBC26B-B2-B2E2C27D25B6(-B2-B2E2CD46A5B)-B2-2BE2(2CD46A5B-B2-B2E)4(2CD46A5B-B2-2BE)6(2CD46A5B-B2-B2E)15(2CD46A5B-B2-2BE)2CD46A5B-B2-B2E3(2CD46A5B-B2-2BE)2CD46A5B-B2-B2E2CD46A5B-B2-2BEBCD46A5B-B2-FBEB4(CD46A5B-B2-4B)CD46A5B-B2-F3BCD46A5B-B2-F2B2C11D6BD34B-B2-F3B11C42B-B2-F3B10C43B-B2-F3B2EBE49B-B2-F56B-B2-F6B16F34B2(-B2-57B)-B2-2F3B4G3B3G22B3F17B-B2-F3B5EB8E39B-B2-FBEB17E36B-B2-FBE20C2(BC)30B-B2-F2E24C30B2(-B2-B2E2C27D25B)5(-B2-B2E2C28D24B)2(-B2-2BE2C28D24B)-B2-2BE2C29D23B-B2-2BE2(2C31D21B-B2-3B)2C31D21B2(-B2-2BE2C25D2B5D20B)2(-B2-B2E2C32D20B)-B2-B2E2C31D21B-B2-B2E2C30D7BDBD12B2(-B2-2BE2C28D24B)-B2-B2E2C27D8BD16B-B2-B2E2C26D9B2D15B-B2-B2E2C26D10B2D14B-B2-2BE2C25D27B3(-B2-2BE2C24D28B)-B2-2BE2C22DB2D27B2(-B2-B2E2C22D30B)-B2-2BE2C22D30B-B2-2BE2C18D34B-B2-2BE2C19D33B2(-B2-2BE2C18D34B)-B2-2BE2C17D3BD31B-B2-2BE2(2C17D35B-B2-3B)2C17D35B-B2-F2B2C17D35B-B2-F3B2(C16D36B-B2-4B)2(C17D35B-B2-4B)C18D34B-B2-F3BC17D35B-B2-F3BC12D2B3D35B-B2-F3B11C42B-B2-F2B11C43B-B2-F5BE4B2E44B-B2-F56B-B2-F5B18F33B2(-B2-57B)-B2-2F6B4G13B3F29B-B2-F4BE2B9E40B-B2-F3B17E36B-B2-FBE18C4BC31B-B2-FBE24C30B-B2-B2E23C2B2C27B-B2-B2E24CB4C25B-B2-B2E22C3B3C2(26B-B2-B2E28C)26B-B2-B2E25C2BC26B-B2-B2E28C26B-B2-2BE26CBC26B-B2-2BE28C26B-B2-3B28C26B-B2-2BE29C25B-B2-3B26C28B-B2-2BE27C3B2C22B-B2-2BE26C4BC23B-B2-FBE27C3BC23B-B2-G2E27C3B2C22B-B2-B2(2E28C2B2C22B-B2-G)2E28CB2C23B-B2-B2E29C25B-B2-G2E28C26B-B2-B2E27C27B-B2-G2E27C27B-B2-B2E27C27B-B2-2BE26C28B-B2-B2E2(23C31B-B2-2BE)24C30B2(-B2-2BE22C32B)-B2-B2E20CBC32B-B2-2BE20C34B2(-B2-2BE18C36B)-B2-2BE17CBC35B-B2-3B17C37B-B2-2BE19C35B2(-B2-3B18C36B)-B2-3B17C2(37B-B2-F3B16C)37B-B2-3B17C37B-B2-3BC2B14C37B-B2-4BCB14C37B-B2-4B15C38B-B2-4B13C40B-B2-F3B12C41B-B2-F2B12C42B-B2-F2B10C44B-B2-F4B3E49B-B2-F5BE50B-B2-F5B19F32B2(-B2-57B)-B2-2F4B7G11B6F27B-B2-F4B11E41B-B2-FB17E38B2(-B2-FBE18C36B)-B2-B2E20CBC32B-B2-B2E20C34B2(-B2-2BE21C33B)2(-B2-2BE23C31B)-B2-FBE23C31B-B2-2BE5CB17C31B-B2-3B5CB18C30B3(-B2-2BE23C31B)-B2-2BE24C30B-B2-2BE26C28B2(-B2-F2E27C27B)3(-B2-G2E27C27B)-B2-G2E28C26B-B2-B2E26CBC26B-B2-G2E27C27B2(-B2-B2E24C30B)2(-B2-B2E22C32B)-B2-B2E17C2B3C32B-B2-2BE16CB6C31B-B2-3B17CB4C32B-B2-3B15C3BCB2C32B-B2-3B16C5BC32B-B2-2BE16C38B-B2-2BE2(15C39B-B2-3B)16C38B-B2-FBE16C38B-B2-2BE2(17C37B-B2-3B)16C38B-B2-3B15C39B-B2-F2B15C39B-B2-5B13C39B-B2-3B2(CB)11C39B-B2-6B11C40B-B2-6B7C2(BC)40B-B2-5B8CBC42B-B2-3B10C44B-B2-F2B9C45B-B2-F2B10C44B-B2-F2B6CB3C44B-B2-F4B4EB2E45B-B2-F5B2E3BE45B-B2-F5B20F31B2(-B2-57B)-B2-2F3B8G10B7F27B-B2-F4B11E41B-B2-F2B18E36B-B2-FB3EB15E36B-B2-F4E3B13E36B-B2-B20E36B3(-B2-2B20E35B)-B2-B22E34B-B2-2B6EB15E33B-B2-FB3E2B16E34B-B2-10B14E33B-B2-10B15E32B-B2-2BE7B14E33B-B2-2B2(2EB)16E33B2(-B2-5B21E31B)-B2-2B13EB11E30B-B2-F27E29B-B2-F14EB12E29B-B2-F28E28B-B2-G16EB12E27B2(-B2-G28E28B)-B2-G29E27B-B2-G27E29B-B2-G26E30B-B2-B25E31B-B2-B20E2B3E31B-B2-B19E37B2(-B2-B17E39B)-B2-2B15E40B-B2-4B13E40B-B2-5B13E39B-B2-2BE2B11E41B-B2-2B7EB4E43B-B2-4B6EB4E42B-B2-4B11E42B-B2-FB13E42B-B2-FB2(17E38B-B2-2B)16E39B-B2-2B16E39B-B2-5B12E40B-B2-4B12E41B-B2-2BE3B10E41B-B2-2BE5B4E2BE42B-B2-6B6E45B-B2-6B3E2B2E44B-B2-4BE2BE3BE45B-B2-8B3E46B-B2-F56B-B2-F4BE4B2E45B-B2-F4B8E44B-B2-F5B6E45B-B2-F5BFG19F30B2(-B2-57B)-B2-2F3BGB6G10B7F27B-B2-F3B12E41B-B2-F4B8E44B-B2-F8B5EB3E2BE36B-B2-9B9E39B-B2-2B2E6B8E39B-B2-3B2E4B9E39B-B2-8B6EB3EB2E36B-B2-9B5E2B5E36B-B2-9B12E36B-B2-9B5EB7E35B-B2-F9B13E34B-B2-11B11E35B-B2-10B12E35B-B2-9B13E35B-B2-10B5E2B6E34B-B2-7B8E2B7E33B-B2-7B9EB5EB2E32B-B2-2(2BE)B6E6B8E30B-B2-F9EB2E3B11E30B-B2-F11EBE2B11E30B-B2-F16E2B10E28B-B2-G15E4B2EB6E28B-B2-G15E4B2E2B2(5E28B-B2-G16E3B3EB)4E29B-B2-G19EB6E30B-B2-G16E2B7E31B-B2-G16E2B3E2B2E31B-B2-B18E38B2(-B2-B17E39B)-B2-BEB13E41B-B2-4BEB10E41B2(-B2-6B9E42B)-B2-6B8E43B-B2-7BEB4E44B-B2-5BEBE3B2E44B-B2-5BE2B5EBE42B-B2-F3B10E43B-B2-F2B3EB8EBE40B-B2-3B3E4B8E39B-B2-3B2E4B8E40B-B2-8B2EB5E41B-B2-9B6E42B-B2-9B2E2B2E42B-B2-7BE6BE42B-B2-7BE49B-B2-8BE48B4(-B2-57B)2(-B2-F56B)-B2-F5B3EB2E45B-B2-F6B2G18F19BF10B2(-B2-57B)-B2-2F6B5G10B6F28B-B2-3F6B3G10B15F20B-B2-3F7B2G8B18F19B-B2-2F8B4G7B18F18B-B2-10B3G9B19F16B-B2-10B3G4B2G4B18F16B-B2-9B4G4BG5B19F15B-B2-9B4G3BG7B19FB8F5B-B2-9B3G13B24F3B3F2B-B2-10B4G13B19F6B5F-B2-10B3G5BG13B14F7B4F-B2-F9B3G5B2G13B12F8B4F-B2-11B2G3B5G13B11F12B-B2-12BG3B5G14B8F14B-B2-10B3GB4FG2F16B4F16B-B2-11BG2B9F34B-B2-9B3G2B6FG2F34B-B2-12B2GB4F3G15B3F17B-B2-6F13B3GBG13B3F17B-B2-G10F8B3GB4G30B-B2-FG2F5G3F2G10B3G30B-B2-14G9B4G30B-B2-15G9B4G29B-B2-15G9B3G24B5FB-B2-15G10B2G20B10F-B2-16G9B2G9B5F6B10F-B2-14GB2G9BG8B6F7BF8B-B2-17G18B5F17B-B2-2B14G19B2F20B-B2-3B13G41B-B2-4B13G40B-B2-4B3G2B8G40B-B2-7B9G41B-B2-3B3F2B7G11B2F29B-B2-3B4FB7G8B8F26B-B2-4B3FGB5G9B9F25B-B2-7B5G12B9F24B-B2-9B3G17B6F20B2F-B2-8B4G17B7F9B12F-B2-10B2G9B4F2B10F7B13F-B2-3F7B2G8B18F5B13FB-B2-3F8BG14B11F5B15F-B2-3B2G28B3F5B16F-B2-12B4G11BF13B16F-B2-12B4F9B6F10B9F3B4F-B2-25B9F8B6F7BFB-B2-26B8F19B3FB-B2-29B5F18B3F2B-B2-14B2F14B3F24B-B2-30B3F24B-B2-42B6F9B-B2-18BF19B19F-B2-18B6F12B10F4B7F-B2-19B4F30B4F-B2-20B3F32B2F-B2-3F54B-B2-3F6B6F31B2F9B-B2-F7BFG18F29B-B2-57B-B3660-
