model
name = main
size = 160 5 160
scale = 0.02 0.1 0.02
origin = -y
shell = Outline 0.25
material type = basic, lighting = smooth, fade = true, side = double, warp = 2 0.5, clamp = -y, skip = x y
  colors = B:#060 C:#0A0 A:#020
material type = basic, lighting = smooth, fade = true, side = double, warp = 2 0.5, clamp = -y, skip = y z
  colors = F:#070 E:#020 G:#0C0
material type = basic, side = double, skip = x -y z
  colors = X:#020
material type = basic, lighting = smooth, roughness = 0, refractionRatio = 1, side = back
  colors = Outline:#000
voxels
20(160X160-20(A3-E3-)20(B3-F3-)20(C7-)160X640-160X162-20(F3-B3-)19(G3-C3-)G3-C161-160X640-160X160-20(A3-E3-)19(B3-F3-)B3-F20(7-G)3-160X640-160X162-20(E3-B3-)19(F3-C3-)F3-C161-160X640-)
